Workbook
Name Full: #REF!
Name Glossary: #REF!
Name scope: #REF!
Name TopOfTable_Table_2: #REF!

Sheet sensitivity>>
A1: Se

Sheet cost_hyper
B1: =B7 -> econ cost 0.5 | C1: =C7 -> econ cost 1 | D1: =D7 -> econ cost 2 | F1: =F7 -> vacc cost 0.5 | G1: =G7 -> vacc cost 1 | H1: =H7 -> vacc cost 2 | J1: =J7 -> hosp cost 0.5 | K1: =K7 -> hosp cost 1 | L1: =L7 -> hosp cost 2
A2: Hosp Cost | B2: 5.84392 | C2: 5.83635 | D2: 5.822396 | F2: 5.828895 | G2: 5.83635 | H2: 5.842176 | J2: 2.916813 | K2: 5.83635 | L2: 11.665745 | P2: 0 Hosp Cost | Q2: 5.84392 | R2: 0 Hosp Cost | S2: 5.822396 | T2: 0 Hosp Cost | U2: 5.828895 | V2: 0 Hosp Cost | W2: 5.842176 | X2: 0 Hosp Cost | Y2: 2.916813 | Z2: 0 Hosp Cost | AA2: 11.665745
A3: Policy Cost | B3: 4.018653 | C3: 4.170264 | D3: 4.601928 | F3: 3.087738 | G3: 4.170264 | H3: 6.222306 | J3: 4.189087 | K3: 4.170264 | L3: 4.202002 | P3: 1 Policy Cost | Q3: 4.018653 | R3: 1 Policy Cost | S3: 4.601928 | T3: 1 Policy Cost | U3: 3.087738 | V3: 1 Policy Cost | W3: 6.222306 | X3: 1 Policy Cost | Y3: 4.189087 | Z3: 1 Policy Cost | AA3: 4.202002
A4: Econ Cost | B4: 14.854796 | C4: 29.697205 | D4: 59.349877 | F4: 29.683279 | G4: 29.697205 | H4: 29.706603 | J4: 29.690989 | K4: 29.697205 | L4: 29.689624 | P4: 2 Econ Cost | Q4: 14.854796 | R4: 2 Econ Cost | S4: 59.349877 | T4: 2 Econ Cost | U4: 29.683279 | V4: 2 Econ Cost | W4: 29.706603 | X4: 2 Econ Cost | Y4: 29.690989 | Z4: 2 Econ Cost | AA4: 29.689624
A5: Total Cost | B5: 24.717369 | C5: 39.70382 | D5: 69.774202 | F5: 38.599911 | G5: 39.70382 | H5: 41.771085 | J5: 36.796889 | K5: 39.70382 | L5: 45.557371 | P5: 3 Total Cost | Q5: 24.717369 | R5: 3 Total Cost | S5: 69.774202 | T5: 3 Total Cost | U5: 38.599911 | V5: 3 Total Cost | W5: 41.771085 | X5: 3 Total Cost | Y5: 36.796889 | Z5: 3 Total Cost | AA5: 45.557371
A7: ori | B7: econ cost 0.5 | C7: econ cost 1 | D7: econ cost 2 | F7: vacc cost 0.5 | G7: vacc cost 1 | H7: vacc cost 2 | J7: hosp cost 0.5 | K7: hosp cost 1 | L7: hosp cost 2 | P7: econ cost 0.5 | R7: econ cost 2 | T7: vacc cost 0.5 | V7: vacc cost 2 | X7: hosp cost 0.5 | Z7: hosp cost 2
A8: =base_vacc!L3 -> 0.02778321 | B8: =AVERAGE(P8:Q8) -> 0.0248226 | C8: =A8 -> 0.02778321 | D8: =AVERAGE(R8:S8) -> 0.02483845 | F8: =AVERAGE(T8:U8) -> 0.0248233 | G8: =A8 -> 0.02778321 | H8: =AVERAGE(V8:W8) -> 0.02482215 | J8: =AVERAGE(X8:Y8) -> 0.02482265 | K8: =A8 -> 0.02778321 | L8: =AVERAGE(Z8:AA8) -> 0.02482335 | M8: =ROUND(L8,4)&"," -> 0.0248, | P8: 0.024833 | Q8: 0.0248122 | R8: 0.0248472 | S8: 0.0248297 | T8: 0.0248336 | U8: 0.024813 | V8: 0.0248326 | W8: 0.0248117 | X8: 0.024833 | Y8: 0.0248123 | Z8: 0.0248337 | AA8: 0.024813
A9: =base_vacc!L4 -> 0.027776404 | B9: =AVERAGE(P9:Q9) -> 0.0248241 | C9: =A9 -> 0.027776404 | D9: =AVERAGE(R9:S9) -> 0.02484115 | F9: =AVERAGE(T9:U9) -> 0.02482485 | G9: =A9 -> 0.027776404 | H9: =AVERAGE(V9:W9) -> 0.0248234 | J9: =AVERAGE(X9:Y9) -> 0.02482405 | K9: =A9 -> 0.027776404 | L9: =AVERAGE(Z9:AA9) -> 0.02482495 | M9: =ROUND(L9,4)&"," -> 0.0248, | P9: 0.0248368 | Q9: 0.0248114 | R9: 0.0248518 | S9: 0.0248305 | T9: 0.0248374 | U9: 0.0248123 | V9: 0.0248361 | W9: 0.0248107 | X9: 0.0248367 | Y9: 0.0248114 | Z9: 0.0248376 | AA9: 0.0248123
A10: =base_vacc!L5 -> 0.02776844 | B10: =AVERAGE(P10:Q10) -> 0.0248166 | C10: =A10 -> 0.02776844 | D10: =AVERAGE(R10:S10) -> 0.0248365 | F10: =AVERAGE(T10:U10) -> 0.0248174 | G10: =A10 -> 0.02776844 | H10: =AVERAGE(V10:W10) -> 0.0248157 | J10: =AVERAGE(X10:Y10) -> 0.0248164 | K10: =A10 -> 0.02776844 | L10: =AVERAGE(Z10:AA10) -> 0.0248177 | M10: =ROUND(L10,4)&"," -> 0.0248, | P10: 0.0248279 | Q10: 0.0248053 | R10: 0.0248457 | S10: 0.0248273 | T10: 0.0248286 | U10: 0.0248062 | V10: 0.0248271 | W10: 0.0248043 | X10: 0.0248277 | Y10: 0.0248051 | Z10: 0.0248289 | AA10: 0.0248065
A11: =base_vacc!L6 -> 0.027758411 | B11: =AVERAGE(P11:Q11) -> 0.0248091 | C11: =A11 -> 0.027758411 | D11: =AVERAGE(R11:S11) -> 0.02483075 | F11: =AVERAGE(T11:U11) -> 0.0248102 | G11: =A11 -> 0.027758411 | H11: =AVERAGE(V11:W11) -> 0.024808 | J11: =AVERAGE(X11:Y11) -> 0.02480895 | K11: =A11 -> 0.027758411 | L11: =AVERAGE(Z11:AA11) -> 0.02481045 | M11: =ROUND(L11,4)&"," -> 0.0248, | P11: 0.0248215 | Q11: 0.0247967 | R11: 0.0248407 | S11: 0.0248208 | T11: 0.0248224 | U11: 0.024798 | V11: 0.0248204 | W11: 0.0247956 | X11: 0.0248213 | Y11: 0.0247966 | Z11: 0.0248227 | AA11: 0.0247982
A12: =base_vacc!L7 -> 0.027740514 | B12: =AVERAGE(P12:Q12) -> 0.02480045 | C12: =A12 -> 0.027740514 | D12: =AVERAGE(R12:S12) -> 0.02482385 | F12: =AVERAGE(T12:U12) -> 0.02480205 | G12: =A12 -> 0.027740514 | H12: =AVERAGE(V12:W12) -> 0.02479925 | J12: =AVERAGE(X12:Y12) -> 0.02480055 | K12: =A12 -> 0.027740514 | L12: =AVERAGE(Z12:AA12) -> 0.02480235 | M12: =ROUND(L12,4)&"," -> 0.0248, | P12: 0.0248116 | Q12: 0.0247893 | R12: 0.024832 | S12: 0.0248157 | T12: 0.024813 | U12: 0.0247911 | V12: 0.0248104 | W12: 0.0247881 | X12: 0.0248116 | Y12: 0.0247895 | Z12: 0.0248133 | AA12: 0.0247914
A13: =base_vacc!L8 -> 0.027715634 | B13: =AVERAGE(P13:Q13) -> 0.0247878 | C13: =A13 -> 0.027715634 | D13: =AVERAGE(R13:S13) -> 0.02481565 | F13: =AVERAGE(T13:U13) -> 0.02479005 | G13: =A13 -> 0.027715634 | H13: =AVERAGE(V13:W13) -> 0.02478635 | J13: =AVERAGE(X13:Y13) -> 0.02478805 | K13: =A13 -> 0.027715634 | L13: =AVERAGE(Z13:AA13) -> 0.02479035 | M13: =ROUND(L13,4)&"," -> 0.0248, | P13: 0.024803 | Q13: 0.0247726 | R13: 0.0248285 | S13: 0.0248028 | T13: 0.024805 | U13: 0.0247751 | V13: 0.0248016 | W13: 0.0247711 | X13: 0.0248031 | Y13: 0.024773 | Z13: 0.0248053 | AA13: 0.0247754
A14: =base_vacc!L9 -> 0.02768686 | B14: =AVERAGE(P14:Q14) -> 0.02477305 | C14: =A14 -> 0.02768686 | D14: =AVERAGE(R14:S14) -> 0.02480325 | F14: =AVERAGE(T14:U14) -> 0.0247765 | G14: =A14 -> 0.02768686 | H14: =AVERAGE(V14:W14) -> 0.0247715 | J14: =AVERAGE(X14:Y14) -> 0.0247739 | K14: =A14 -> 0.02768686 | L14: =AVERAGE(Z14:AA14) -> 0.0247766 | M14: =ROUND(L14,4)&"," -> 0.0248, | P14: 0.0247858 | Q14: 0.0247603 | R14: 0.0248152 | S14: 0.0247913 | T14: 0.0247891 | U14: 0.0247639 | V14: 0.0247843 | W14: 0.0247587 | X14: 0.0247866 | Y14: 0.0247612 | Z14: 0.0247892 | AA14: 0.024764
A15: =base_vacc!L10 -> 0.027651986 | B15: =AVERAGE(P15:Q15) -> 0.0247539 | C15: =A15 -> 0.027651986 | D15: =AVERAGE(R15:S15) -> 0.0247916 | F15: =AVERAGE(T15:U15) -> 0.0247589 | G15: =A15 -> 0.027651986 | H15: =AVERAGE(V15:W15) -> 0.02475205 | J15: =AVERAGE(X15:Y15) -> 0.0247555 | K15: =A15 -> 0.027651986 | L15: =AVERAGE(Z15:AA15) -> 0.0247589 | M15: =ROUND(L15,4)&"," -> 0.0248, | P15: 0.024766 | Q15: 0.0247418 | R15: 0.0248016 | S15: 0.0247816 | T15: 0.0247709 | U15: 0.0247469 | V15: 0.0247641 | W15: 0.02474 | X15: 0.0247675 | Y15: 0.0247435 | Z15: 0.0247709 | AA15: 0.0247469
A16: =base_vacc!L11 -> 0.027605466 | B16: =AVERAGE(P16:Q16) -> 0.02473275 | C16: =A16 -> 0.027605466 | D16: =AVERAGE(R16:S16) -> 0.02477755 | F16: =AVERAGE(T16:U16) -> 0.02474065 | G16: =A16 -> 0.027605466 | H16: =AVERAGE(V16:W16) -> 0.02473085 | J16: =AVERAGE(X16:Y16) -> 0.02473605 | K16: =A16 -> 0.027605466 | L16: =AVERAGE(Z16:AA16) -> 0.0247402 | M16: =ROUND(L16,4)&"," -> 0.0247, | P16: 0.0247353 | Q16: 0.0247302 | R16: 0.0247858 | S16: 0.0247693 | T16: 0.0247441 | U16: 0.0247372 | V16: 0.0247334 | W16: 0.0247283 | X16: 0.0247391 | Y16: 0.024733 | Z16: 0.0247436 | AA16: 0.0247368
A17: =base_vacc!L12 -> 0.027535294 | B17: =AVERAGE(P17:Q17) -> 0.02470645 | C17: =A17 -> 0.027535294 | D17: =AVERAGE(R17:S17) -> 0.0247557 | F17: =AVERAGE(T17:U17) -> 0.02471785 | G17: =A17 -> 0.027535294 | H17: =AVERAGE(V17:W17) -> 0.02470415 | J17: =AVERAGE(X17:Y17) -> 0.02471165 | K17: =A17 -> 0.027535294 | L17: =AVERAGE(Z17:AA17) -> 0.0247169 | M17: =ROUND(L17,4)&"," -> 0.0247, | P17: 0.0247189 | Q17: 0.024694 | R17: 0.0247701 | S17: 0.0247413 | T17: 0.0247303 | U17: 0.0247054 | V17: 0.0247168 | W17: 0.0246915 | X17: 0.0247243 | Y17: 0.024699 | Z17: 0.0247293 | AA17: 0.0247045
A18: =base_vacc!L13 -> 0.027460909 | B18: =AVERAGE(P18:Q18) -> 0.0246499 | C18: =A18 -> 0.027460909 | D18: =AVERAGE(R18:S18) -> 0.0247213 | F18: =AVERAGE(T18:U18) -> 0.02467215 | G18: =A18 -> 0.027460909 | H18: =AVERAGE(V18:W18) -> 0.0246486 | J18: =AVERAGE(X18:Y18) -> 0.0246625 | K18: =A18 -> 0.027460909 | L18: =AVERAGE(Z18:AA18) -> 0.02466915 | M18: =ROUND(L18,4)&"," -> 0.0247, | P18: 0.0246626 | Q18: 0.0246372 | R18: 0.0247288 | S18: 0.0247138 | T18: 0.0246842 | U18: 0.0246601 | V18: 0.0246606 | W18: 0.0246366 | X18: 0.0246744 | Y18: 0.0246506 | Z18: 0.0246818 | AA18: 0.0246565
A19: =base_vacc!L14 -> 0.027376611 | B19: =AVERAGE(P19:Q19) -> 0.0246019 | C19: =A19 -> 0.027376611 | D19: =AVERAGE(R19:S19) -> 0.02466245 | F19: =AVERAGE(T19:U19) -> 0.0246348 | G19: =A19 -> 0.027376611 | H19: =AVERAGE(V19:W19) -> 0.02460185 | J19: =AVERAGE(X19:Y19) -> 0.0246217 | K19: =A19 -> 0.027376611 | L19: =AVERAGE(Z19:AA19) -> 0.0246297 | M19: =ROUND(L19,4)&"," -> 0.0246, | P19: 0.0246416 | Q19: 0.0245622 | R19: 0.0246973 | S19: 0.0246276 | T19: 0.0246676 | U19: 0.024602 | V19: 0.0246396 | W19: 0.0245641 | X19: 0.0246561 | Y19: 0.0245873 | Z19: 0.0246642 | AA19: 0.0245952
... A67: =base_vacc!L62 -> 0.004243431 | B67: =AVERAGE(P67:Q67) -> 0.00515867 | C67: =A67 -> 0.004243431 | D67: =AVERAGE(R67:S67) -> 0.00515873 | F67: =AVERAGE(T67:U67) -> 0.0051433 | G67: =A67 -> 0.004243431 | H67: =AVERAGE(V67:W67) -> 0.005173145 | J67: =AVERAGE(X67:Y67) -> 0.00515867 | K67: =A67 -> 0.004243431 | L67: =AVERAGE(Z67:AA67) -> 0.00515867 | M67: =ROUND(L67,4)&"," -> 0.0052, | P67: 0.00516653 | Q67: 0.00515081 | R67: 0.00516662 | S67: 0.00515084 | T67: 0.00515004 | U67: 0.00513656 | V67: 0.00518203 | W67: 0.00516426 | X67: 0.00516653 | Y67: 0.00515081 | Z67: 0.00516653 | AA67: 0.00515081

Sheet para_val
B1: =B7 -> sigma=0.01 | C1: =C7 -> sigma=0.05 (base) | D1: =D7 -> sigma=0.1 | E1: =E7 -> sigma=0.2 | F1: =F7 -> sigma=0.3 | G1: =G7 -> sigma=0.4 | H1: =H7 -> sigma=0.5 | J1: =J7 -> beta3*0.1 | K1: =K7 -> beta3*0.5 | L1: =L7 -> beta3*1 (base) | M1: =M7 -> beta3*2 | N1: =N7 -> beta3*3 | P1: =P7 -> delta3*0.5 | Q1: =Q7 -> delta3*1 | R1: =R7 -> delta3*2 | S1: =S7 -> delta1*0.5 | T1: =T7 -> delta1*2 | U1: =U7 -> delta23*0.5 | V1: =V7 -> delta23*2
A2: Hosp Cost | B2: 5.519248 | C2: 5.83635 | D2: 6.038377 | E2: 6.730515 | F2: 7.576262 | G2: 8.61775 | H2: 9.915519 | J2: 3.021547 | K2: 3.884077 | L2: 5.83635 | M2: 17.821244 | N2: 50.982044 | P2: 28.053339 | Q2: =C2 -> 5.83635 | R2: 1.776207 | S2: 23.772361 | T2: 2.132929 | U2: 7.259313 | V2: 5.178956
A3: Policy Cost | B3: 4.074666 | C3: 4.170264 | D3: 4.271672 | E3: 4.534862 | F3: 4.85714 | G3: 5.267555 | H3: 5.751265 | J3: 3.15276 | K3: 3.465212 | L3: 4.170264 | M3: 8.692018 | N3: 21.19033 | P3: 6.904405 | Q3: =C3 -> 4.170264 | R3: 3.470562 | S3: 6.832825 | T3: 3.472372 | U3: 4.204561 | V3: 4.182084
A4: Econ Cost | B4: 27.988069 | C4: 29.697205 | D4: 30.801153 | E4: 34.549299 | F4: 39.12923 | G4: 44.779469 | H4: 51.818102 | J4: 14.470685 | K4: 19.124871 | L4: 29.697205 | M4: 94.57006 | N4: 274.95426 | P4: 97.071066 | Q4: =C4 -> 29.697205 | R4: 14.440788 | S4: 95.994437 | T4: 14.540292 | U4: 30.060926 | V4: 29.477529
A5: Total Cost | B5: 37.581983 | C5: 39.70382 | D5: 41.111203 | E5: 45.814675 | F5: 51.562632 | G5: 58.664773 | H5: 67.484886 | J5: 20.644993 | K5: 26.47416 | L5: 39.70382 | M5: 121.08332 | N5: 347.12664 | P5: 132.02881 | Q5: =C5 -> 39.70382 | R5: 19.687558 | S5: 126.59962 | T5: 20.145593 | U5: 41.5248 | V5: 38.838569
A7: ori | B7: sigma=0.01 | C7: sigma=0.05 (base) | D7: sigma=0.1 | E7: sigma=0.2 | F7: sigma=0.3 | G7: sigma=0.4 | H7: sigma=0.5 | J7: beta3*0.1 | K7: beta3*0.5 | L7: beta3*1 (base) | M7: beta3*2 | N7: beta3*3 | P7: delta3*0.5 | Q7: delta3*1 | R7: delta3*2 | S7: delta1*0.5 | T7: delta1*2 | U7: delta23*0.5 | V7: delta23*2 | AA7: sigma0.01 | AC7: sigma0.1 | AE7: sigma*0.75 | AG7: sigma0.2 | AI7: sigma0.3 | AK7: sigma0.4 | AM7: sigma0.5 | AP7: beta3*0.1 | AR7: beta3*0.5 | AT7: beta3*2 | AV7: beta3*3 | AY7: beta1*0.5 | BA7: beta1*2 | BD7: delta3*0.5 | BF7: delta3*2 | BI7: delta1*0.5 | BK7: delta1*2 | BM7: delta23*0.5 | BO7: delta23*2
A8: =base_vacc!L3 -> 0.02778321 | B8: =AVERAGE(AA8:AB8) -> 0.02482285 | C8: =A8 -> 0.02778321 | D8: =AVERAGE(AC8:AD8) -> 0.02482295 | E8: =AVERAGE(AG8:AH8) -> 0.02482305 | F8: =AVERAGE(AI8:AJ8) -> 0.02482315 | G8: =AVERAGE(AK8:AL8) -> 0.02482355 | H8: =AVERAGE(AM8:AN8) -> 0.02482355 | J8: =AVERAGE(AP8:AQ8) -> 0.0248225 | K8: =AVERAGE(AR8:AS8) -> 0.02482255 | L8: =A8 -> 0.02778321 | M8: =AVERAGE(AT8:AU8) -> 0.0248258 | N8: =AVERAGE(AV8:AW8) -> 0.0248321 | P8: =AVERAGE(BD8:BE8) -> 0.0248257 | Q8: =A8 -> 0.02778321 | R8: =AVERAGE(BF8:BG8) -> 0.02482235 | S8: =AVERAGE(BI8:BJ8) -> 0.02482555 | T8: =AVERAGE(BK8:BL8) -> 0.02482245 | U8: =AVERAGE(BM8:BN8) -> 0.02482305 | V8: =AVERAGE(BO8:BP8) -> 0.02482275 | X8: =ROUND(V8,4)&"," -> 0.0248, | AA8: 0.0248332 | AB8: 0.0248125 | AC8: 0.0248333 | AD8: 0.0248126 | AE8: 0.0248339 | AF8: 0.0248132 | AG8: 0.0248334 | AH8: 0.0248127 | AI8: 0.0248335 | AJ8: 0.0248128 | AK8: 0.0248339 | AL8: 0.0248132 | AM8: 0.0248339 | AN8: 0.0248132 | AP8: 0.0248329 | AQ8: 0.0248121 | AR8: 0.0248329 | AS8: 0.0248122 | AT8: 0.0248359 | AU8: 0.0248157 | AV8: 0.024841 | AW8: 0.0248232 | AY8: 0.0248329 | AZ8: 0.0248122 | BA8: 0.0248359 | BB8: 0.0248157 | BD8: 0.0248359 | BE8: 0.0248155 | BF8: 0.0248327 | BG8: 0.024812 | BI8: 0.0248358 | BJ8: 0.0248153 | BK8: 0.0248328 | BL8: 0.0248121 | BM8: 0.0248334 | BN8: 0.0248127 | BO8: 0.0248331 | BP8: 0.0248124
A9: =base_vacc!L4 -> 0.027776404 | B9: =AVERAGE(AA9:AB9) -> 0.0248243 | C9: =A9 -> 0.027776404 | D9: =AVERAGE(AC9:AD9) -> 0.02482435 | E9: =AVERAGE(AG9:AH9) -> 0.02482445 | F9: =AVERAGE(AI9:AJ9) -> 0.0248246 | G9: =AVERAGE(AK9:AL9) -> 0.024825 | H9: =AVERAGE(AM9:AN9) -> 0.024825 | J9: =AVERAGE(AP9:AQ9) -> 0.0248239 | K9: =AVERAGE(AR9:AS9) -> 0.02482395 | L9: =A9 -> 0.027776404 | M9: =AVERAGE(AT9:AU9) -> 0.02482805 | N9: =AVERAGE(AV9:AW9) -> 0.02483585 | P9: =AVERAGE(BD9:BE9) -> 0.02482835 | Q9: =A9 -> 0.027776404 | R9: =AVERAGE(BF9:BG9) -> 0.0248236 | S9: =AVERAGE(BI9:BJ9) -> 0.0248278 | T9: =AVERAGE(BK9:BL9) -> 0.0248238 | U9: =AVERAGE(BM9:BN9) -> 0.02482485 | V9: =AVERAGE(BO9:BP9) -> 0.0248241 | X9: =ROUND(V9,4)&"," -> 0.0248, | AA9: 0.0248369 | AB9: 0.0248117 | AC9: 0.024837 | AD9: 0.0248117 | AE9: 0.0248377 | AF9: 0.0248123 | AG9: 0.0248371 | AH9: 0.0248118 | AI9: 0.0248373 | AJ9: 0.0248119 | AK9: 0.0248377 | AL9: 0.0248123 | AM9: 0.0248377 | AN9: 0.0248123 | AP9: 0.0248365 | AQ9: 0.0248113 | AR9: 0.0248366 | AS9: 0.0248113 | AT9: 0.0248405 | AU9: 0.0248156 | AV9: 0.024847 | AW9: 0.0248247 | AY9: 0.0248366 | AZ9: 0.0248113 | BA9: 0.0248405 | BB9: 0.0248156 | BD9: 0.0248409 | BE9: 0.0248158 | BF9: 0.0248363 | BG9: 0.0248109 | BI9: 0.0248404 | BJ9: 0.0248152 | BK9: 0.0248365 | BL9: 0.0248111 | BM9: 0.0248374 | BN9: 0.0248123 | BO9: 0.0248367 | BP9: 0.0248115
A10: =base_vacc!L5 -> 0.02776844 | B10: =AVERAGE(AA10:AB10) -> 0.0248168 | C10: =A10 -> 0.02776844 | D10: =AVERAGE(AC10:AD10) -> 0.0248169 | E10: =AVERAGE(AG10:AH10) -> 0.024817 | F10: =AVERAGE(AI10:AJ10) -> 0.02481715 | G10: =AVERAGE(AK10:AL10) -> 0.02481755 | H10: =AVERAGE(AM10:AN10) -> 0.02481755 | J10: =AVERAGE(AP10:AQ10) -> 0.0248165 | K10: =AVERAGE(AR10:AS10) -> 0.0248165 | L10: =A10 -> 0.02776844 | M10: =AVERAGE(AT10:AU10) -> 0.02482085 | N10: =AVERAGE(AV10:AW10) -> 0.02482975 | P10: =AVERAGE(BD10:BE10) -> 0.02482165 | Q10: =A10 -> 0.02776844 | R10: =AVERAGE(BF10:BG10) -> 0.02481605 | S10: =AVERAGE(BI10:BJ10) -> 0.02482075 | T10: =AVERAGE(BK10:BL10) -> 0.02481625 | U10: =AVERAGE(BM10:BN10) -> 0.02481765 | V10: =AVERAGE(BO10:BP10) -> 0.0248165 | X10: =ROUND(V10,4)&"," -> 0.0248, | AA10: 0.0248281 | AB10: 0.0248055 | AC10: 0.0248282 | AD10: 0.0248056 | AE10: 0.0248288 | AF10: 0.0248063 | AG10: 0.0248283 | AH10: 0.0248057 | AI10: 0.0248284 | AJ10: 0.0248059 | AK10: 0.0248288 | AL10: 0.0248063 | AM10: 0.0248288 | AN10: 0.0248063 | AP10: 0.0248278 | AQ10: 0.0248052 | AR10: 0.0248278 | AS10: 0.0248052 | AT10: 0.0248316 | AU10: 0.0248101 | AV10: 0.0248389 | AW10: 0.0248206 | AY10: 0.0248278 | AZ10: 0.0248052 | BA10: 0.0248315 | BB10: 0.02481 | BD10: 0.0248324 | BE10: 0.0248109 | BF10: 0.0248274 | BG10: 0.0248047 | BI10: 0.0248316 | BJ10: 0.0248099 | BK10: 0.0248276 | BL10: 0.0248049 | BM10: 0.0248288 | BN10: 0.0248065 | BO10: 0.0248278 | BP10: 0.0248052
A11: =base_vacc!L6 -> 0.027758411 | B11: =AVERAGE(AA11:AB11) -> 0.0248094 | C11: =A11 -> 0.027758411 | D11: =AVERAGE(AC11:AD11) -> 0.0248095 | E11: =AVERAGE(AG11:AH11) -> 0.0248096 | F11: =AVERAGE(AI11:AJ11) -> 0.02480975 | G11: =AVERAGE(AK11:AL11) -> 0.0248102 | H11: =AVERAGE(AM11:AN11) -> 0.0248102 | J11: =AVERAGE(AP11:AQ11) -> 0.024809 | K11: =AVERAGE(AR11:AS11) -> 0.02480905 | L11: =A11 -> 0.027758411 | M11: =AVERAGE(AT11:AU11) -> 0.0248144 | N11: =AVERAGE(AV11:AW11) -> 0.02482545 | P11: =AVERAGE(BD11:BE11) -> 0.02481585 | Q11: =A11 -> 0.027758411 | R11: =AVERAGE(BF11:BG11) -> 0.02480825 | S11: =AVERAGE(BI11:BJ11) -> 0.02481445 | T11: =AVERAGE(BK11:BL11) -> 0.02480855 | U11: =AVERAGE(BM11:BN11) -> 0.02481055 | V11: =AVERAGE(BO11:BP11) -> 0.02480895 | X11: =ROUND(V11,4)&"," -> 0.0248, | AA11: 0.0248217 | AB11: 0.0247971 | AC11: 0.0248218 | AD11: 0.0247972 | AE11: 0.0248226 | AF11: 0.0247978 | AG11: 0.0248219 | AH11: 0.0247973 | AI11: 0.0248221 | AJ11: 0.0247974 | AK11: 0.0248226 | AL11: 0.0247978 | AM11: 0.0248226 | AN11: 0.0247978 | AP11: 0.0248212 | AQ11: 0.0247968 | AR11: 0.0248213 | AS11: 0.0247968 | AT11: 0.0248265 | AU11: 0.0248023 | AV11: 0.0248359 | AW11: 0.024815 | AY11: 0.0248213 | AZ11: 0.0247968 | BA11: 0.0248264 | BB11: 0.0248022 | BD11: 0.0248279 | BE11: 0.0248038 | BF11: 0.0248207 | BG11: 0.0247958 | BI11: 0.0248266 | BJ11: 0.0248023 | BK11: 0.024821 | BL11: 0.0247961 | BM11: 0.0248227 | BN11: 0.0247984 | BO11: 0.0248213 | BP11: 0.0247966
A12: =base_vacc!L7 -> 0.027740514 | B12: =AVERAGE(AA12:AB12) -> 0.02480105 | C12: =A12 -> 0.027740514 | D12: =AVERAGE(AC12:AD12) -> 0.02480115 | E12: =AVERAGE(AG12:AH12) -> 0.02480125 | F12: =AVERAGE(AI12:AJ12) -> 0.0248014 | G12: =AVERAGE(AK12:AL12) -> 0.0248018 | H12: =AVERAGE(AM12:AN12) -> 0.0248018 | J12: =AVERAGE(AP12:AQ12) -> 0.0248008 | K12: =AVERAGE(AR12:AS12) -> 0.02480075 | L12: =A12 -> 0.027740514 | M12: =AVERAGE(AT12:AU12) -> 0.02480655 | N12: =AVERAGE(AV12:AW12) -> 0.02482035 | P12: =AVERAGE(BD12:BE12) -> 0.02480865 | Q12: =A12 -> 0.027740514 | R12: =AVERAGE(BF12:BG12) -> 0.0248 | S12: =AVERAGE(BI12:BJ12) -> 0.0248068 | T12: =AVERAGE(BK12:BL12) -> 0.02480035 | U12: =AVERAGE(BM12:BN12) -> 0.02480255 | V12: =AVERAGE(BO12:BP12) -> 0.02480045 | X12: =ROUND(V12,4)&"," -> 0.0248, | AA12: 0.0248121 | AB12: 0.02479 | AC12: 0.0248122 | AD12: 0.0247901 | AE12: 0.0248129 | AF12: 0.0247907 | AG12: 0.0248123 | AH12: 0.0247902 | AI12: 0.0248125 | AJ12: 0.0247903 | AK12: 0.0248129 | AL12: 0.0247907 | AM12: 0.0248129 | AN12: 0.0247907 | AP12: 0.0248119 | AQ12: 0.0247897 | AR12: 0.0248118 | AS12: 0.0247897 | AT12: 0.0248171 | AU12: 0.024796 | AV12: 0.0248291 | AW12: 0.0248116 | AY12: 0.0248118 | AZ12: 0.0247897 | BA12: 0.024817 | BB12: 0.0247959 | BD12: 0.0248192 | BE12: 0.0247981 | BF12: 0.0248113 | BG12: 0.0247887 | BI12: 0.0248175 | BJ12: 0.0247961 | BK12: 0.0248116 | BL12: 0.0247891 | BM12: 0.0248135 | BN12: 0.0247916 | BO12: 0.0248115 | BP12: 0.0247894
A13: =base_vacc!L8 -> 0.027715634 | B13: =AVERAGE(AA13:AB13) -> 0.02478875 | C13: =A13 -> 0.027715634 | D13: =AVERAGE(AC13:AD13) -> 0.0247889 | E13: =AVERAGE(AG13:AH13) -> 0.024789 | F13: =AVERAGE(AI13:AJ13) -> 0.0247892 | G13: =AVERAGE(AK13:AL13) -> 0.0247896 | H13: =AVERAGE(AM13:AN13) -> 0.0247896 | J13: =AVERAGE(AP13:AQ13) -> 0.02478835 | K13: =AVERAGE(AR13:AS13) -> 0.0247882 | L13: =A13 -> 0.027715634 | M13: =AVERAGE(AT13:AU13) -> 0.0247958 | N13: =AVERAGE(AV13:AW13) -> 0.02481335 | P13: =AVERAGE(BD13:BE13) -> 0.0247989 | Q13: =A13 -> 0.027715634 | R13: =AVERAGE(BF13:BG13) -> 0.02478785 | S13: =AVERAGE(BI13:BJ13) -> 0.02479615 | T13: =AVERAGE(BK13:BL13) -> 0.0247882 | U13: =AVERAGE(BM13:BN13) -> 0.02479075 | V13: =AVERAGE(BO13:BP13) -> 0.0247879 | X13: =ROUND(V13,4)&"," -> 0.0248, | AA13: 0.0248038 | AB13: 0.0247737 | AC13: 0.0248039 | AD13: 0.0247739 | AE13: 0.0248046 | AF13: 0.0247746 | AG13: 0.024804 | AH13: 0.024774 | AI13: 0.0248042 | AJ13: 0.0247742 | AK13: 0.0248046 | AL13: 0.0247746 | AM13: 0.0248046 | AN13: 0.0247746 | AP13: 0.0248033 | AQ13: 0.0247734 | AR13: 0.0248032 | AS13: 0.0247732 | AT13: 0.0248101 | AU13: 0.0247815 | AV13: 0.0248257 | AW13: 0.024801 | AY13: 0.0248032 | AZ13: 0.0247732 | BA13: 0.02481 | BB13: 0.0247813 | BD13: 0.0248132 | BE13: 0.0247846 | BF13: 0.0248032 | BG13: 0.0247725 | BI13: 0.0248107 | BJ13: 0.0247816 | BK13: 0.0248035 | BL13: 0.0247729 | BM13: 0.0248056 | BN13: 0.0247759 | BO13: 0.024803 | BP13: 0.0247728
A14: =base_vacc!L9 -> 0.02768686 | B14: =AVERAGE(AA14:AB14) -> 0.0247747 | C14: =A14 -> 0.02768686 | D14: =AVERAGE(AC14:AD14) -> 0.0247749 | E14: =AVERAGE(AG14:AH14) -> 0.02477505 | F14: =AVERAGE(AI14:AJ14) -> 0.02477525 | G14: =AVERAGE(AK14:AL14) -> 0.02477555 | H14: =AVERAGE(AM14:AN14) -> 0.02477555 | J14: =AVERAGE(AP14:AQ14) -> 0.02477375 | K14: =AVERAGE(AR14:AS14) -> 0.0247738 | L14: =A14 -> 0.02768686 | M14: =AVERAGE(AT14:AU14) -> 0.02478265 | N14: =AVERAGE(AV14:AW14) -> 0.0248043 | P14: =AVERAGE(BD14:BE14) -> 0.02478725 | Q14: =A14 -> 0.02768686 | R14: =AVERAGE(BF14:BG14) -> 0.0247723 | S14: =AVERAGE(BI14:BJ14) -> 0.0247836 | T14: =AVERAGE(BK14:BL14) -> 0.02477275 | U14: =AVERAGE(BM14:BN14) -> 0.0247773 | V14: =AVERAGE(BO14:BP14) -> 0.02477365 | X14: =ROUND(V14,4)&"," -> 0.0248, | AA14: 0.0247874 | AB14: 0.024762 | AC14: 0.0247876 | AD14: 0.0247622 | AE14: 0.0247882 | AF14: 0.0247629 | AG14: 0.0247877 | AH14: 0.0247624 | AI14: 0.0247879 | AJ14: 0.0247626 | AK14: 0.0247882 | AL14: 0.0247629 | AM14: 0.0247882 | AN14: 0.0247629 | AP14: 0.0247868 | AQ14: 0.0247607 | AR14: 0.0247866 | AS14: 0.024761 | AT14: 0.0247949 | AU14: 0.0247704 | AV14: 0.0248146 | AW14: 0.024794 | AY14: 0.0247867 | AZ14: 0.0247611 | BA14: 0.0247947 | BB14: 0.0247701 | BD14: 0.0247995 | BE14: 0.024775 | BF14: 0.0247856 | BG14: 0.024759 | BI14: 0.024796 | BJ14: 0.0247712 | BK14: 0.024786 | BL14: 0.0247595 | BM14: 0.0247899 | BN14: 0.0247647 | BO14: 0.0247864 | BP14: 0.0247609
A15: =base_vacc!L10 -> 0.027651986 | B15: =AVERAGE(AA15:AB15) -> 0.02475655 | C15: =A15 -> 0.027651986 | D15: =AVERAGE(AC15:AD15) -> 0.0247568 | E15: =AVERAGE(AG15:AH15) -> 0.0247569 | F15: =AVERAGE(AI15:AJ15) -> 0.0247571 | G15: =AVERAGE(AK15:AL15) -> 0.0247574 | H15: =AVERAGE(AM15:AN15) -> 0.0247574 | J15: =AVERAGE(AP15:AQ15) -> 0.0247559 | K15: =AVERAGE(AR15:AS15) -> 0.0247558 | L15: =A15 -> 0.027651986 | M15: =AVERAGE(AT15:AU15) -> 0.0247665 | N15: =AVERAGE(AV15:AW15) -> 0.02479435 | P15: =AVERAGE(BD15:BE15) -> 0.02477335 | Q15: =A15 -> 0.027651986 | R15: =AVERAGE(BF15:BG15) -> 0.0247548 | S15: =AVERAGE(BI15:BJ15) -> 0.0247683 | T15: =AVERAGE(BK15:BL15) -> 0.0247553 | U15: =AVERAGE(BM15:BN15) -> 0.0247598 | V15: =AVERAGE(BO15:BP15) -> 0.02475515 | X15: =ROUND(V15,4)&"," -> 0.0248, | AA15: 0.0247686 | AB15: 0.0247445 | AC15: 0.0247688 | AD15: 0.0247448 | AE15: 0.0247693 | AF15: 0.0247455 | AG15: 0.0247689 | AH15: 0.0247449 | AI15: 0.0247691 | AJ15: 0.0247451 | AK15: 0.0247693 | AL15: 0.0247455 | AM15: 0.0247693 | AN15: 0.0247455 | AP15: 0.0247679 | AQ15: 0.0247439 | AR15: 0.0247679 | AS15: 0.0247437 | AT15: 0.024778 | AU15: 0.024755 | AV15: 0.0248051 | AW15: 0.0247836 | AY15: 0.024768 | AZ15: 0.0247437 | BA15: 0.0247777 | BB15: 0.0247547 | BD15: 0.0247855 | BE15: 0.0247612 | BF15: 0.0247668 | BG15: 0.0247428 | BI15: 0.0247805 | BJ15: 0.0247561 | BK15: 0.0247673 | BL15: 0.0247433 | BM15: 0.0247718 | BN15: 0.0247478 | BO15: 0.0247672 | BP15: 0.0247431
A16: =base_vacc!L11 -> 0.027605466 | B16: =AVERAGE(AA16:AB16) -> 0.02473725 | C16: =A16 -> 0.027605466 | D16: =AVERAGE(AC16:AD16) -> 0.0247376 | E16: =AVERAGE(AG16:AH16) -> 0.02473785 | F16: =AVERAGE(AI16:AJ16) -> 0.02473815 | G16: =AVERAGE(AK16:AL16) -> 0.0247383 | H16: =AVERAGE(AM16:AN16) -> 0.0247383 | J16: =AVERAGE(AP16:AQ16) -> 0.0247343 | K16: =AVERAGE(AR16:AS16) -> 0.0247358 | L16: =A16 -> 0.027605466 | M16: =AVERAGE(AT16:AU16) -> 0.02474735 | N16: =AVERAGE(AV16:AW16) -> 0.02477905 | P16: =AVERAGE(BD16:BE16) -> 0.0247586 | Q16: =A16 -> 0.027605466 | R16: =AVERAGE(BF16:BG16) -> 0.02473295 | S16: =AVERAGE(BI16:BJ16) -> 0.0247514 | T16: =AVERAGE(BK16:BL16) -> 0.0247336 | U16: =AVERAGE(BM16:BN16) -> 0.0247418 | V16: =AVERAGE(BO16:BP16) -> 0.0247353 | X16: =ROUND(V16,4)&"," -> 0.0247, | AA16: 0.0247404 | AB16: 0.0247341 | AC16: 0.0247408 | AD16: 0.0247344 | AE16: 0.0247414 | AF16: 0.0247352 | AG16: 0.024741 | AH16: 0.0247347 | AI16: 0.0247414 | AJ16: 0.0247349 | AK16: 0.0247414 | AL16: 0.0247352 | AM16: 0.0247414 | AN16: 0.0247352 | AP16: 0.024735 | AQ16: 0.0247336 | AR16: 0.0247378 | AS16: 0.0247338 | AT16: 0.0247511 | AU16: 0.0247436 | AV16: 0.0247816 | AW16: 0.0247765 | AY16: 0.0247379 | AZ16: 0.0247338 | BA16: 0.0247507 | BB16: 0.0247433 | BD16: 0.0247648 | BE16: 0.0247524 | BF16: 0.0247348 | BG16: 0.0247311 | BI16: 0.0247567 | BJ16: 0.0247461 | BK16: 0.0247356 | BL16: 0.0247316 | BM16: 0.0247456 | BN16: 0.024738 | BO16: 0.0247381 | BP16: 0.0247325
A17: =base_vacc!L12 -> 0.027535294 | B17: =AVERAGE(AA17:AB17) -> 0.02471325 | C17: =A17 -> 0.027535294 | D17: =AVERAGE(AC17:AD17) -> 0.0247136 | E17: =AVERAGE(AG17:AH17) -> 0.0247139 | F17: =AVERAGE(AI17:AJ17) -> 0.02471425 | G17: =AVERAGE(AK17:AL17) -> 0.02471455 | H17: =AVERAGE(AM17:AN17) -> 0.02471455 | J17: =AVERAGE(AP17:AQ17) -> 0.0247095 | K17: =AVERAGE(AR17:AS17) -> 0.0247119 | L17: =A17 -> 0.027535294 | M17: =AVERAGE(AT17:AU17) -> 0.0247264 | N17: =AVERAGE(AV17:AW17) -> 0.0247702 | P17: =AVERAGE(BD17:BE17) -> 0.0247415 | Q17: =A17 -> 0.027535294 | R17: =AVERAGE(BF17:BG17) -> 0.02470715 | S17: =AVERAGE(BI17:BJ17) -> 0.0247319 | T17: =AVERAGE(BK17:BL17) -> 0.0247079 | U17: =AVERAGE(BM17:BN17) -> 0.02471875 | V17: =AVERAGE(BO17:BP17) -> 0.02471085 | X17: =ROUND(V17,4)&"," -> 0.0247, | AA17: 0.0247258 | AB17: 0.0247007 | AC17: 0.0247261 | AD17: 0.0247011 | AE17: 0.0247266 | AF17: 0.0247025 | AG17: 0.0247263 | AH17: 0.0247015 | AI17: 0.0247266 | AJ17: 0.0247019 | AK17: 0.0247266 | AL17: 0.0247025 | AM17: 0.0247266 | AN17: 0.0247025 | AP17: 0.0247187 | AQ17: 0.0247003 | AR17: 0.0247237 | AS17: 0.0247001 | AT17: 0.0247382 | AU17: 0.0247146 | AV17: 0.0247809 | AW17: 0.0247595 | AY17: 0.0247238 | AZ17: 0.0247001 | BA17: 0.0247377 | BB17: 0.0247141 | BD17: 0.0247536 | BE17: 0.0247294 | BF17: 0.0247166 | BG17: 0.0246977 | BI17: 0.0247443 | BJ17: 0.0247195 | BK17: 0.0247174 | BL17: 0.0246984 | BM17: 0.0247312 | BN17: 0.0247063 | BO17: 0.0247235 | BP17: 0.0246982
A18: =base_vacc!L13 -> 0.027460909 | B18: =AVERAGE(AA18:AB18) -> 0.02466435 | C18: =A18 -> 0.027460909 | D18: =AVERAGE(AC18:AD18) -> 0.02466505 | E18: =AVERAGE(AG18:AH18) -> 0.02466565 | F18: =AVERAGE(AI18:AJ18) -> 0.0246662 | G18: =AVERAGE(AK18:AL18) -> 0.02466635 | H18: =AVERAGE(AM18:AN18) -> 0.02466635 | J18: =AVERAGE(AP18:AQ18) -> 0.02465765 | K18: =AVERAGE(AR18:AS18) -> 0.0246605 | L18: =A18 -> 0.027460909 | M18: =AVERAGE(AT18:AU18) -> 0.02467655 | N18: =AVERAGE(AV18:AW18) -> 0.0247321 | P18: =AVERAGE(BD18:BE18) -> 0.0247047 | Q18: =A18 -> 0.027460909 | R18: =AVERAGE(BF18:BG18) -> 0.02465515 | S18: =AVERAGE(BI18:BJ18) -> 0.0246883 | T18: =AVERAGE(BK18:BL18) -> 0.02465625 | U18: =AVERAGE(BM18:BN18) -> 0.02467295 | V18: =AVERAGE(BO18:BP18) -> 0.02466045 | X18: =ROUND(V18,4)&"," -> 0.0247, | AA18: 0.0246763 | AB18: 0.0246524 | AC18: 0.0246774 | AD18: 0.0246527 | AE18: 0.0246803 | AF18: 0.0246525 | AG18: 0.0246785 | AH18: 0.0246528 | AI18: 0.0246795 | AJ18: 0.0246529 | AK18: 0.0246803 | AL18: 0.0246524 | AM18: 0.0246803 | AN18: 0.0246524 | AP18: 0.0246605 | AQ18: 0.0246548 | AR18: 0.0246685 | AS18: 0.0246525 | AT18: 0.0246939 | AU18: 0.0246592 | AV18: 0.0247567 | AW18: 0.0247075 | AY18: 0.0246687 | AZ18: 0.0246526 | BA18: 0.0246931 | BB18: 0.0246583 | BD18: 0.024722 | BE18: 0.0246874 | BF18: 0.0246578 | BG18: 0.0246525 | BI18: 0.0247064 | BJ18: 0.0246702 | BK18: 0.0246591 | BL18: 0.0246534 | BM18: 0.024685 | BN18: 0.0246609 | BO18: 0.0246722 | BP18: 0.0246487
A19: =base_vacc!L14 -> 0.027376611 | B19: =AVERAGE(AA19:AB19) -> 0.02462405 | C19: =A19 -> 0.027376611 | D19: =AVERAGE(AC19:AD19) -> 0.0246248 | E19: =AVERAGE(AG19:AH19) -> 0.02462525 | F19: =AVERAGE(AI19:AJ19) -> 0.02462575 | G19: =AVERAGE(AK19:AL19) -> 0.0246252 | H19: =AVERAGE(AM19:AN19) -> 0.0246252 | J19: =AVERAGE(AP19:AQ19) -> 0.02462555 | K19: =AVERAGE(AR19:AS19) -> 0.02462515 | L19: =A19 -> 0.027376611 | M19: =AVERAGE(AT19:AU19) -> 0.0246262 | N19: =AVERAGE(AV19:AW19) -> 0.02466 | P19: =AVERAGE(BD19:BE19) -> 0.02467765 | Q19: =A19 -> 0.027376611 | R19: =AVERAGE(BF19:BG19) -> 0.0246188 | S19: =AVERAGE(BI19:BJ19) -> 0.0246554 | T19: =AVERAGE(BK19:BL19) -> 0.0246198 | U19: =AVERAGE(BM19:BN19) -> 0.02463515 | V19: =AVERAGE(BO19:BP19) -> 0.0246192 | X19: =ROUND(V19,4)&"," -> 0.0246, | AA19: 0.0246587 | AB19: 0.0245894 | AC19: 0.0246592 | AD19: 0.0245904 | AE19: 0.0246606 | AF19: 0.02459 | AG19: 0.0246597 | AH19: 0.0245908 | AI19: 0.0246603 | AJ19: 0.0245912 | AK19: 0.0246606 | AL19: 0.0245898 | AM19: 0.0246606 | AN19: 0.0245898 | AP19: 0.0246575 | AQ19: 0.0245936 | AR19: 0.024658 | AS19: 0.0245923 | AT19: 0.0246785 | AU19: 0.0245739 | AV19: 0.0247508 | AW19: 0.0245692 | AY19: 0.0246581 | AZ19: 0.0245925 | BA19: 0.0246775 | BB19: 0.0245725 | BD19: 0.0247089 | BE19: 0.0246464 | BF19: 0.0246528 | BG19: 0.0245848 | BI19: 0.0246907 | BJ19: 0.0246201 | BK19: 0.0246538 | BL19: 0.0245858 | BM19: 0.0246678 | BN19: 0.0246025 | BO19: 0.0246545 | BP19: 0.0245839
... A67: =base_vacc!L62 -> 0.004243431 | B67: =AVERAGE(AA67:AB67) -> 0.00515867 | C67: =A67 -> 0.004243431 | D67: =AVERAGE(AC67:AD67) -> 0.00515867 | E67: =AVERAGE(AG67:AH67) -> 0.00515867 | F67: =AVERAGE(AI67:AJ67) -> 0.00515867 | G67: =AVERAGE(AK67:AL67) -> 0.00515869 | H67: =AVERAGE(AM67:AN67) -> 0.00515869 | J67: =AVERAGE(AP67:AQ67) -> 0.005158615 | K67: =AVERAGE(AR67:AS67) -> 0.00515863 | L67: =A67 -> 0.004243431 | M67: =AVERAGE(AT67:AU67) -> 0.005158665 | N67: =AVERAGE(AV67:AW67) -> 0.00515866 | P67: =AVERAGE(BD67:BE67) -> 0.00515867 | Q67: =A67 -> 0.004243431 | R67: =AVERAGE(BF67:BG67) -> 0.00515862 | S67: =AVERAGE(BI67:BJ67) -> 0.005158675 | T67: =AVERAGE(BK67:BL67) -> 0.00515862 | U67: =AVERAGE(BM67:BN67) -> 0.00515867 | V67: =AVERAGE(BO67:BP67) -> 0.00515867 | X67: =ROUND(V67,4)&"," -> 0.0052, | AA67: 0.00516653 | AB67: 0.00515081 | AC67: 0.00516653 | AD67: 0.00515081 | AE67: 0.00516657 | AF67: 0.00515081 | AG67: 0.00516653 | AH67: 0.00515081 | AI67: 0.00516653 | AJ67: 0.00515081 | AK67: 0.00516657 | AL67: 0.00515081 | AM67: 0.00516657 | AN67: 0.00515081 | AP67: 0.00516645 | AQ67: 0.00515078 | AR67: 0.00516647 | AS67: 0.00515079 | AT67: 0.00516654 | AU67: 0.00515079 | AV67: 0.00516654 | AW67: 0.00515078 | AY67: 0.00516647 | AZ67: 0.00515079 | BA67: 0.00516653 | BB67: 0.00515079 | BD67: 0.00516654 | BE67: 0.0051508 | BF67: 0.00516645 | BG67: 0.00515079 | BI67: 0.00516655 | BJ67: 0.0051508 | BK67: 0.00516645 | BL67: 0.00515079 | BM67: 0.00516653 | BN67: 0.00515081 | BO67: 0.00516653 | BP67: 0.00515081

Sheet Results>>

Sheet reg control
C2: top | K2: k0 = 0.0067 | L2: k0 = 0.0053 | N2: k0 low 0.0053 | O2: k0 high 0.0067 | S2: Strategy 1 | T2: Strategy 2 | U2: Optimal Control
C3: k0 = 0.0067 | F3: vaccination_rate | I3: bottom | K3: k1 = -0.1006 | L3: k1 = -0.1676 | M3: baseline | N3: k1 high -0.1006 | O3: k1 low -0.1676 | S3: Constant Vaccination | T3: Actual alpha | U3: control_1 | V3: control_2 | W3: control_3 | X3: control_4 | Y3: control_5 | AB3: avg over rounds
C4: k1 = -0.1006 | F4: 0.02779241 | I4: k0 = 0.0053 | J4: 1 | K4: =F4 -> 0.02779241 | L4: 0.02779236 | M4: =AB4 -> 0.02447724 | N4: 0.02779235 | O4: 0.02779241 | S4: =$F$3 -> vaccination_rate | T4: =[1]Reg_30days!AJ32 -> 0 | U4: 0.0245031 | V4: 0.0244278 | W4: 0.0244835 | X4: 0.0244886 | Y4: 0.0244832 | AB4: =AVERAGE(U4:Y4) -> 0.02447724
F5: 0.02779357 | I5: k1 = -0.1676 | J5: 2 | K5: =F5 -> 0.02779357 | L5: 0.02779371 | M5: =AB5 -> 0.02438572 | N5: 0.02779351 | O5: 0.02779376 | S5: =$F$3 -> vaccination_rate | T5: =[1]Reg_30days!AJ33 -> 0 | U5: 0.0244224 | V5: 0.0243765 | W5: 0.0243693 | X5: 0.0243777 | Y5: 0.0243827 | AB5: =AVERAGE(U5:Y5) -> 0.02438572
F6: 0.02777892 | J6: 3 | K6: =F6 -> 0.02777892 | L6: 0.02777925 | M6: =AB6 -> 0.0242678 | N6: 0.02777886 | O6: 0.0277793 | S6: =$F$3 -> vaccination_rate | T6: =[1]Reg_30days!AJ34 -> 0 | U6: 0.0243032 | V6: 0.0242313 | W6: 0.0242684 | X6: 0.0242707 | Y6: 0.0242654 | AB6: =AVERAGE(U6:Y6) -> 0.0242678
F7: 0.02776494 | J7: 4 | K7: =F7 -> 0.02776494 | L7: 0.02776547 | M7: =AB7 -> 0.02410956 | N7: 0.02776487 | O7: 0.02776553 | S7: =$F$3 -> vaccination_rate | T7: =[1]Reg_30days!AJ35 -> 0 | U7: 0.0241285 | V7: 0.0241053 | W7: 0.0240692 | X7: 0.024107 | Y7: 0.0241378 | AB7: =AVERAGE(U7:Y7) -> 0.02410956
F8: 0.02774444 | J8: 5 | K8: =F8 -> 0.02774444 | L8: 0.02774524 | M8: =AB8 -> 0.02387136 | N8: 0.02774436 | O8: 0.0277453 | S8: =$F$3 -> vaccination_rate | T8: =[1]Reg_30days!AJ36 -> 0 | U8: 0.02399 | V8: 0.0237615 | W8: 0.0239481 | X8: 0.0239716 | Y8: 0.0236856 | AB8: =AVERAGE(U8:Y8) -> 0.02387136
F9: 0.02771779 | J9: 6 | K9: =F9 -> 0.02771779 | L9: 0.02771905 | M9: =AB9 -> 0.02355274 | N9: 0.02771771 | O9: 0.02771912 | S9: =$F$3 -> vaccination_rate | T9: =[1]Reg_30days!AJ37 -> 0 | U9: 0.0239124 | V9: 0.023483 | W9: 0.0234279 | X9: 0.0233801 | Y9: 0.0235603 | AB9: =AVERAGE(U9:Y9) -> 0.02355274
F10: 0.02769106 | J10: 7 | K10: =F10 -> 0.02769106 | L10: 0.02769274 | M10: =AB10 -> 0.02338316 | N10: 0.02769097 | O10: 0.0276928 | S10: =$F$3 -> vaccination_rate | T10: =[1]Reg_30days!AJ38 -> 0 | U10: 0.0235616 | V10: 0.0234558 | W10: 0.0234109 | X10: 0.0231867 | Y10: 0.0233008 | AB10: =AVERAGE(U10:Y10) -> 0.02338316
F11: 0.02765664 | J11: 8 | K11: =F11 -> 0.02765664 | L11: 0.02765901 | M11: =AB11 -> 0.02316708 | N11: 0.02765656 | O11: 0.02765907 | S11: =$F$3 -> vaccination_rate | T11: =[1]Reg_30days!AJ39 -> 0 | U11: 0.0231953 | V11: 0.0231481 | W11: 0.02331 | X11: 0.0231032 | Y11: 0.0230788 | AB11: =AVERAGE(U11:Y11) -> 0.02316708
F12: 0.02761797 | J12: 9 | K12: =F12 -> 0.02761797 | L12: 0.02762101 | M12: =AB12 -> 0.02305654 | N12: 0.02761784 | O12: 0.0276211 | S12: =$F$3 -> vaccination_rate | T12: =[1]Reg_30days!AJ40 -> 0 | U12: 0.0230804 | V12: 0.0229861 | W12: 0.0233851 | X12: 0.0229123 | Y12: 0.0229188 | AB12: =AVERAGE(U12:Y12) -> 0.02305654
F13: 0.02759025 | J13: 10 | K13: =F13 -> 0.02759025 | L13: 0.02759398 | M13: =AB13 -> 0.02285692 | N13: 0.02759015 | O13: 0.02759403 | S13: =$F$3 -> vaccination_rate | T13: =[1]Reg_30days!AJ41 -> 0 | U13: 0.022797 | V13: 0.0226103 | W13: 0.0232388 | X13: 0.0229475 | Y13: 0.022691 | AB13: =AVERAGE(U13:Y13) -> 0.02285692
F14: 0.02758413 | J14: 11 | K14: =F14 -> 0.02758413 | L14: 0.02758989 | M14: =AB14 -> 0.02267136 | N14: 0.02758616 | O14: 0.02758931 | S14: =$F$3 -> vaccination_rate | T14: =[1]Reg_30days!AJ42 -> 0 | U14: 0.0225398 | V14: 0.0225778 | W14: 0.0229953 | X14: 0.0226186 | Y14: 0.0226253 | AB14: =AVERAGE(U14:Y14) -> 0.02267136
F15: 0.02747588 | J15: 12 | K15: =F15 -> 0.02747588 | L15: 0.02748173 | M15: =AB15 -> 0.02247434 | N15: 0.02747582 | O15: 0.02748176 | S15: =$F$3 -> vaccination_rate | T15: =[1]Reg_30days!AJ43 -> 0 | U15: 0.0223361 | V15: 0.0225738 | W15: 0.022726 | X15: 0.0224946 | Y15: 0.0222412 | AB15: =AVERAGE(U15:Y15) -> 0.02247434
F16: 0.02734684 | J16: 13 | K16: =F16 -> 0.02734684 | L16: 0.02735633 | M16: =AB16 -> 0.02239424 | N16: 0.02734733 | O16: 0.027356 | S16: =$F$3 -> vaccination_rate | T16: =[1]Reg_30days!AJ44 -> 0 | U16: 0.0221573 | V16: 0.0222858 | W16: 0.0225789 | X16: 0.0226736 | Y16: 0.0222756 | AB16: =AVERAGE(U16:Y16) -> 0.02239424
F17: 0.02724283 | J17: 14 | K17: =F17 -> 0.02724283 | L17: 0.0272533 | M17: =AB17 -> 0.02230826 | N17: 0.02724293 | O17: 0.02725343 | S17: =$F$3 -> vaccination_rate | T17: =[1]Reg_30days!AJ45 -> 0 | U17: 0.0226141 | V17: 0.0222929 | W17: 0.0225579 | X17: 0.0223482 | Y17: 0.0217282 | AB17: =AVERAGE(U17:Y17) -> 0.02230826
... F63: 0.00424856 | J63: 60 | K63: =F63 -> 0.00424856 | L63: 0.00424851 | M63: =AB63 -> 0.005159404 | N63: 0.00424854 | O63: 0.00424854 | S63: =$F$3 -> vaccination_rate | T63: =[1]Reg_30days!AJ91 -> 0 | U63: 0.00516643 | V63: 0.00515081 | W63: 0.00516471 | X63: 0.00515668 | Y63: 0.00515839 | AB63: =AVERAGE(U63:Y63) -> 0.005159404
S70: upper
E71: lower | AE71: base | AQ71: k1low | BC71: k0 low
AQ72: k0 high | BC72: k1 high
G84: Strategy | H84: Total Cost | I84: Healthcare | J84: Policy | K84: Economic | L84: Cost reduction
G85: No Vaccination | H85: 38.72 | I85: 9.5 | J85: 1.66 | K85: 27.56 | L85: =1-H88/H85 -> 0.17742769
G86: Constant Vaccination | H86: 34.28 | I86: 8.13 | J86: 3.08 | K86: 23.07 | L86: =1-H88/H86 -> 0.070886814
G87: Actual (Government) | H87: 31.4 | I87: 4.93 | J87: 3.35 | K87: 23.12
G88: Optimal | H88: 31.85 | I88: 4.42 | J88: 5.89 | K88: 21.54
E101: standard
E111: peak infected | F111: hosp | G111: icu
D112: no | AQ112: Strategy | AR112: Peak Infected | AS112: Peak Mild | AT112: Peak Hosp | AU112: Peak ICU | AV112: Peak Infected | AW112: Peak Mild | AX112: Peak Hosp | AY112: Peak ICU | BC112: Strategy | BD112: Peak Infected | BE112: Peak Mild | BF112: Peak Hosp | BG112: Peak ICU | BH112: Peak Infected | BI112: Peak Mild | BJ112: Peak Hosp | BK112: Peak ICU
D113: constant | AQ113: No Vaccination | AR113: 0.5662 | AS113: 0.5421 | AT113: 0.02185 | AU113: 0.01598 | AV113: =1-AR116/AR113 -> 0.0060049452 | AW113: =1-AS116/AS113 -> -0.027116768 | AX113: =1-AT116/AT113 -> 0.65629291 | AY113: =1-AU116/AU113 -> 0.8097622 | BC113: No Vaccination | BD113: 0.5662 | BE113: 0.5421 | BF113: 0.02185 | BG113: 0.01598 | BH113: =1-BD116/BD113 -> 0.0060049452 | BI113: =1-BE116/BE113 -> -0.026194429 | BJ113: =1-BF116/BF113 -> 0.65629291 | BK113: =1-BG116/BG113 -> 0.79411765
D114: optimal | S114: Strategy | T114: Peak Infected | U114: Peak Mild | V114: Peak Hosp | W114: Peak ICU | X114: Peak Infected | Y114: Peak Mild | Z114: Peak Hosp | AA114: Peak ICU | AQ114: Constant Vaccination | AR114: 0.5632 | AS114: 0.5395 | AT114: 0.02161 | AU114: 0.01551 | AV114: =1-AR116/AR114 -> 0.00071022727 | AW114: =1-AS116/AS114 -> -0.032066728 | AX114: =1-AT116/AT114 -> 0.65247571 | AY114: =1-AU116/AU114 -> 0.80399742 | BC114: Constant Vaccination | BD114: 0.5632 | BE114: 0.5395 | BF114: 0.02161 | BG114: 0.01551 | BH114: =1-BD116/BD114 -> 0.00071022727 | BI114: =1-BE116/BE114 -> -0.031139944 | BJ114: =1-BF116/BF114 -> 0.65247571 | BK114: =1-BG116/BG114 -> 0.78787879
F115: Strategy | G115: Peak Infected | H115: Peak Mild | I115: Peak Hosp | J115: Peak ICU | K115: Peak Infected | L115: Peak Mild | M115: Peak Hosp | N115: Peak ICU | S115: No Vaccination | T115: 0.5662 | U115: 0.5421 | V115: 0.02185 | W115: 0.01598 | X115: =1-T118/T115 -> 0.0061815613 | Y115: =1-U118/U115 -> -0.023058476 | Z115: =1-V118/V115 -> 0.65583524 | AA115: =1-W118/W115 -> 0.73404255 | AE115: Strategy | AF115: Peak Infected | AG115: Peak Mild | AH115: Peak Hosp | AI115: Peak ICU | AJ115: Peak Infected | AK115: Peak Mild | AL115: Peak Hosp | AM115: Peak ICU | AQ115: Actual (Government) | AR115: 0.5649 | AS115: 0.5564 | AT115: 0.00752 | AU115: 0.0043 | BC115: Actual (Government) | BD115: 0.5649 | BE115: 0.5569 | BF115: 0.00752 | BG115: 0.00408
F116: No Vaccination | G116: 0.5662 | H116: 0.5421 | I116: 0.02185 | J116: 0.01598 | K116: =1-G119/G116 -> 0.0058283292 | L116: =1-H119/H116 -> -0.02951485 | M116: =1-I119/I116 -> 0.65629291 | N116: =1-J119/J116 -> 0.83291615 | S116: Constant Vaccination | T116: 0.5632 | U116: 0.5395 | V116: 0.02161 | W116: 0.01551 | X116: =1-T118/T116 -> 0.00088778409 | Y116: =1-U118/U116 -> -0.027988879 | Z116: =1-V118/V116 -> 0.65201296 | AA116: =1-W118/W116 -> 0.72598324 | AE116: No Vaccination | AF116: 0.5662 | AG116: 0.5421 | AH116: 0.02185 | AI116: 0.01598 | AJ116: =1-AF119/AF116 -> 0.0060049452 | AK116: =1-AG119/AG116 -> -0.026563365 | AL116: =1-AH119/AH116 -> 0.65629291 | AM116: =1-AI119/AI116 -> 0.80162703 | AQ116: Optimal | AR116: 0.5628 | AS116: 0.5568 | AT116: 0.00751 | AU116: 0.00304 | BC116: Optimal | BD116: 0.5628 | BE116: 0.5563 | BF116: 0.00751 | BG116: 0.00329
F117: Constant Vaccination | G117: 0.5632 | H117: 0.5395 | I117: 0.02161 | J117: 0.01551 | K117: =1-G119/G117 -> 0.00053267045 | L117: =1-H119/H117 -> -0.034476367 | M117: =1-I119/I117 -> 0.65247571 | N117: =1-J119/J117 -> 0.827853 | S117: Actual (Government) | T117: 0.5648 | U117: 0.5552 | V117: 0.00757 | W117: 0.00512 | AE117: Constant Vaccination | AF117: 0.5632 | AG117: 0.5395 | AH117: 0.02161 | AI117: 0.01551 | AJ117: =1-AF119/AF117 -> 0.00071022727 | AK117: =1-AG119/AG117 -> -0.031510658 | AL117: =1-AH119/AH117 -> 0.65247571 | AM117: =1-AI119/AI117 -> 0.79561573
F118: Actual (Government) | G118: 0.565 | H118: 0.5581 | I118: 0.00751 | J118: 0.0034 | S118: Optimal | T118: 0.5627 | U118: 0.5546 | V118: 0.00752 | W118: 0.00425 | AE118: Actual (Government) | AF118: 0.5649 | AG118: 0.5567 | AH118: 0.00752 | AI118: 0.00419
F119: Optimal | G119: 0.5629 | H119: 0.5581 | I119: 0.00751 | J119: 0.00267 | AE119: Optimal | AF119: 0.5628 | AG119: 0.5565 | AH119: 0.00751 | AI119: 0.00317 | AQ119: Table 3: Peak Infection (Mean, absolute numbers) | BC119: Table 3: Peak Infection (Mean, absolute numbers)
F121: Strategy | G121: Peak Infected | H121: Peak Mild | I121: Peak Hosp | J121: Peak ICU | K121: Peak Infected | L121: Peak Mild | M121: Peak Hosp | N121: Peak ICU | AQ121: Strategy | AR121: Peak Infected | AS121: Peak Mild | AT121: Peak Hosp | AU121: Peak ICU | BC121: Strategy | BD121: Peak Infected | BE121: Peak Mild | BF121: Peak Hosp | BG121: Peak ICU
F122: No Vaccination | G122: 37539 | H122: 35941 | I122: 1448 | J122: 1059 | K122: =1-G125/G122 -> 0.0058072937 | L122: =1-H125/H122 -> -0.029437133 | M122: =1-I125/I122 -> 0.65607735 | N122: =1-J125/J122 -> 0.83286119 | AE122: Table 3: Peak Infection (Mean, absolute numbers) | AQ122: No Vaccination | AR122: 37539 | AS122: 35941 | AT122: 1448 | AU122: 1059 | BC122: No Vaccination | BD122: 37539 | BE122: 35941 | BF122: 1448 | BG122: 1059
F123: Constant Vaccination | G123: 37338 | H123: 35769 | I123: 1433 | J123: 1028 | K123: =1-G125/G123 -> 0.00045530023 | L123: =1-H125/H123 -> -0.034387319 | M123: =1-I125/I123 -> 0.65247732 | N123: =1-J125/J123 -> 0.82782101 | S123: Strategy | T123: Peak Infected | U123: Peak Mild | V123: Peak Hosp | W123: Peak ICU | AQ123: Constant Vaccination | AR123: 37338 | AS123: 35769 | AT123: 1433 | AU123: 1028 | BC123: Constant Vaccination | BD123: 37338 | BE123: 35769 | BF123: 1433 | BG123: 1028
F124: Actual (Government) | G124: 37460 | H124: 37002 | I124: 498 | J124: 225 | S124: No Vaccination | T124: 37539 | U124: 35941 | V124: 1448 | W124: 1059 | AE124: Strategy | AF124: Peak Infected | AG124: Peak Mild | AH124: Peak Hosp | AI124: Peak ICU | AQ124: Actual (Government) | AR124: 37452 | AS124: 36889 | AT124: 498 | AU124: 285 | BC124: Actual (Government) | BD124: 37454 | BE124: 36923 | BF124: 498 | BG124: 271
F125: Optimal | G125: 37321 | H125: 36999 | I125: 498 | J125: 177 | S125: Constant Vaccination | T125: 37338 | U125: 35769 | V125: 1433 | W125: 1028 | AE125: No Vaccination | AF125: 37539 | AG125: 35941 | AH125: 1448 | AI125: 1059 | AQ125: Optimal | AR125: 37315 | AS125: 36916 | AT125: 498 | AU125: 202 | BC125: Optimal | BD125: 37313 | BE125: 36879 | BF125: 498 | BG125: 218
...

Sheet reg cost
C1: high, high | D1: low,low | F1: low, high | G1: high, low
C2: k0 = 0.0067 | D2: k0 = 0.0053 | F2: k0 low 0.0053 | G2: k0 high 0.0067
C3: k1 = -0.1006 | D3: k1 = -0.1676 | F3: k1 high -0.1006 | G3: k1 low -0.1676 | J3: =0.0009+0.00009*5 -> 0.00135
J4: =0.0123+0.00123*5 -> 0.01845
C9: high, high | K9: low,low | S9: low, high | AA9: high, low | AI9: baseline
C10: Outcome Metric | D10: No Vacc | E10: Constant | F10: Actual | G10: Optimal | H10: Actual vs No | I10: Optimal vs No | K10: Outcome Metric | L10: No Vacc | M10: Constant | N10: Actual | O10: Optimal | P10: Actual vs No | Q10: Optimal vs No | S10: Outcome Metric | T10: No Vacc | U10: Constant | V10: Actual | W10: Optimal | X10: Actual vs No | Y10: Optimal vs No | AA10: Outcome Metric | AB10: No Vacc | AC10: Constant | AD10: Actual | AE10: Optimal | AF10: Actual vs No | AG10: Optimal vs No | AI10: Outcome Metric | AJ10: No Vacc | AK10: Constant | AL10: Actual | AM10: Optimal | AN10: Actual vs No | AO10: Optimal vs No
C12: Epidemiological outcomes | K12: Epidemiological outcomes | S12: Epidemiological outcomes | AA12: Epidemiological outcomes | AI12: Epidemiological outcomes
C13: Peak infection prevalence (%) | D13: 0.566 | E13: 0.563 | F13: 0.565 | G13: 0.563 | H13: -0.002 | I13: -0.006 | K13: Peak infection prevalence (%) | L13: 0.566 | M13: 0.563 | N13: 0.565 | O13: 0.563 | P13: -0.002 | Q13: -0.006 | S13: Peak infection prevalence (%) | T13: 0.566 | U13: 0.563 | V13: 0.565 | W13: 0.563 | X13: -0.002 | Y13: -0.006 | AA13: Peak infection prevalence (%) | AB13: 0.566 | AC13: 0.563 | AD13: 0.565 | AE13: 0.563 | AF13: -0.002 | AG13: -0.006 | AI13: Peak infection prevalence (%) | AJ13: 0.566 | AK13: 0.563 | AL13: 0.565 | AM13: 0.563 | AN13: -0.002 | AO13: -0.006
C14: Peak hospitalised (persons) | D14: 1448 | E14: 1433 | F14: 502 | G14: 498 | H14: -0.653 | I14: -0.656 | K14: Peak hospitalised (persons) | L14: 1448 | M14: 1433 | N14: 498 | O14: 498 | P14: -0.656 | Q14: -0.656 | S14: Peak hospitalised (persons) | T14: 1448 | U14: 1433 | V14: 498 | W14: 498 | X14: -0.656 | Y14: -0.656 | AA14: Peak hospitalised (persons) | AB14: 1448 | AC14: 1433 | AD14: 498 | AE14: 498 | AF14: -0.656 | AG14: -0.656 | AI14: Peak hospitalised (persons) | AJ14: 1448 | AK14: 1433 | AL14: 498 | AM14: 498 | AN14: -0.656 | AO14: -0.656
C15: Peak ICU (persons) | D15: 1059 | E15: 1028 | F15: 339 | G15: 282 | H15: -0.68 | I15: -0.734 | K15: Peak ICU (persons) | L15: 1059 | M15: 1028 | N15: 225 | O15: 177 | P15: -0.787 | Q15: -0.833 | S15: Peak ICU (persons) | T15: 1059 | U15: 1028 | V15: 271 | W15: 219 | X15: -0.744 | Y15: -0.794 | AA15: Peak ICU (persons) | AB15: 1059 | AC15: 1028 | AD15: 285 | AE15: 202 | AF15: -0.731 | AG15: -0.809 | AI15: Peak ICU (persons) | AJ15: 1059 | AK15: 1028 | AL15: 278 | AM15: 210 | AN15: -0.738 | AO15: -0.802 | AP15: =AO15-AN15 -> -0.064
C16: Cumulative hospital-days | D16: 27456 | E16: 23439 | F16: 7155 | G16: 5944 | H16: -0.739 | I16: -0.784 | K16: Cumulative hospital-days | L16: 27456 | M16: 23439 | N16: 3750 | O16: 2432 | P16: -0.863 | Q16: -0.911 | S16: Cumulative hospital-days | T16: 27456 | U16: 23439 | V16: 5388 | W16: 4274 | X16: -0.804 | Y16: -0.844 | AA16: Cumulative hospital-days | AB16: 27456 | AC16: 23439 | AD16: 5511 | AE16: 3819 | AF16: -0.799 | AG16: -0.861 | AI16: Cumulative hospital-days | AJ16: 27456 | AK16: 23439 | AL16: 5450 | AM16: 4042 | AN16: -0.802 | AO16: -0.853 | AP16: =AO16-AN16 -> -0.051
C17: Cumulative ICU-days | D17: 27063 | E17: 23496 | F17: 7689 | G17: 6517 | H17: -0.716 | I17: -0.759 | K17: Cumulative ICU-days | L17: 27063 | M17: 23496 | N17: 4379 | O17: 3095 | P17: -0.838 | Q17: -0.886 | S17: Cumulative ICU-days | T17: 27063 | U17: 23496 | V17: 5973 | W17: 4892 | X17: -0.779 | Y17: -0.819 | AA17: Cumulative ICU-days | AB17: 27063 | AC17: 23496 | AD17: 6089 | AE17: 4444 | AF17: -0.775 | AG17: -0.836 | AI17: Cumulative ICU-days | AJ17: 27063 | AK17: 23496 | AL17: 6031 | AM17: 4663 | AN17: -0.777 | AO17: -0.828
C18: Cumulative deaths | D18: 110.9 | E18: 96 | F18: 29.9 | G18: 25 | H18: -0.73 | I18: -0.774 | K18: Cumulative deaths | L18: 110.9 | M18: 96 | N18: 16.1 | O18: 10.7 | P18: -0.855 | Q18: -0.903 | S18: Cumulative deaths | T18: 110.9 | U18: 96 | V18: 22.8 | W18: 18.2 | X18: -0.795 | Y18: -0.836 | AA18: Cumulative deaths | AB18: 110.9 | AC18: 96 | AD18: 23.2 | AE18: 16.4 | AF18: -0.79 | AG18: -0.852 | AI18: Cumulative deaths | AJ18: 110.9 | AK18: 96 | AL18: 23 | AM18: 17.3 | AN18: -0.793 | AO18: -0.844
C20: Cost outcomes (units) | K20: Cost outcomes (units) | S20: Cost outcomes (units) | AA20: Cost outcomes (units) | AI20: Cost outcomes (units)
C21: Vaccination costs | D21: 0 | E21: 1.71 | F21: 1.96 | G21: 2.42 | H21: – | I21: – | K21: Vaccination costs | L21: 0 | M21: 1.71 | N21: 1.96 | O21: 2.43 | P21: – | Q21: – | S21: Vaccination costs | T21: 0 | U21: 1.71 | V21: 1.96 | W21: 2.42 | X21: – | Y21: – | AA21: Vaccination costs | AB21: 0 | AC21: 1.71 | AD21: 1.96 | AE21: 2.43 | AF21: – | AG21: – | AI21: Vaccination costs | AJ21: 0 | AK21: 1.71 | AL21: 1.96 | AM21: 2.45 | AN21: – | AO21: –
C22: Quarantine costs | D22: 1.66 | E22: 1.37 | F22: 1.39 | G22: 1.29 | H22: -0.165 | I22: -0.221 | K22: Quarantine costs | L22: 1.66 | M22: 1.37 | N22: 1.39 | O22: 1.3 | P22: -0.161 | Q22: -0.218 | S22: Quarantine costs | T22: 1.66 | U22: 1.37 | V22: 1.39 | W22: 1.3 | X22: -0.163 | Y22: -0.219 | AA22: Quarantine costs | AB22: 1.66 | AC22: 1.37 | AD22: 1.39 | AE22: 1.3 | AF22: -0.163 | AG22: -0.219 | AI22: Quarantine costs | AJ22: 1.66 | AK22: 1.37 | AL22: 1.39 | AM22: 1.3 | AN22: -0.163 | AO22: -0.219
C23: Healthcare costs | D23: 9.5 | E23: 8.13 | F23: 5.48 | G23: 5.03 | H23: -0.424 | I23: -0.471 | K23: Healthcare costs | L23: 9.5 | M23: 8.13 | N23: 4.93 | O23: 4.46 | P23: -0.481 | Q23: -0.531 | S23: Healthcare costs | T23: 9.5 | U23: 8.13 | V23: 5.2 | W23: 4.76 | X23: -0.453 | Y23: -0.499 | AA23: Healthcare costs | AB23: 9.5 | AC23: 8.13 | AD23: 5.21 | AE23: 4.68 | AF23: -0.451 | AG23: -0.507 | AI23: Healthcare costs | AJ23: 9.5 | AK23: 8.13 | AL23: 5.21 | AM23: 4.72 | AN23: -0.452 | AO23: -0.503
C24: Economic productivity loss | D24: 27.56 | E24: 23.07 | F24: 23.07 | G24: 21.6 | H24: -0.163 | I24: -0.216 | K24: Economic productivity loss | L24: 27.56 | M24: 23.07 | N24: 23.12 | O24: 21.64 | P24: -0.161 | Q24: -0.215 | S24: Economic productivity loss | T24: 27.56 | U24: 23.07 | V24: 23.1 | W24: 21.62 | X24: -0.162 | Y24: -0.215 | AA24: Economic productivity loss | AB24: 27.56 | AC24: 23.07 | AD24: 23.09 | AE24: 21.62 | AF24: -0.162 | AG24: -0.215 | AI24: Economic productivity loss | AJ24: 27.56 | AK24: 23.07 | AL24: 23.09 | AM24: 21.62 | AN24: -0.162 | AO24: -0.216
C25: Total cost | D25: 38.72 | E25: 34.28 | F25: 31.89 | G25: 30.35 | H25: -0.176 | I25: -0.216 | K25: Total cost | L25: 38.72 | M25: 34.28 | N25: 31.4 | O25: 29.82 | P25: -0.189 | Q25: -0.23 | S25: Total cost | T25: 38.72 | U25: 34.28 | V25: 31.64 | W25: 30.1 | X25: -0.183 | Y25: -0.223 | AA25: Total cost | AB25: 38.72 | AC25: 34.28 | AD25: 31.65 | AE25: 30.03 | AF25: -0.182 | AG25: -0.224 | AI25: Total cost | AJ25: 38.72 | AK25: 34.28 | AL25: 31.65 | AM25: 30.08 | AN25: -0.183 | AO25: -0.223

Sheet range
B1: min-max*70% | C1: min-max*80% | E1: min-max*90% | F1: min-max (base) | L1: min-max*70% | R1: min-max*80% | X1: min-max*90% | AD1: min-max (base) | AJ1: min-max 0.85 | AP1: min-max 1.15 | AZ1: no vacc | BA1: constant vacc | BB1: actual vacc | BC1: min-max*70% | BD1: min-max*80% | BE1: min-max*90% | BF1: min-max (base)
A2: Hosp Cost | B2: =P3 -> 6.268083 | C2: =V3 -> 6.087827 | E2: =AB3 -> 5.758631 | F2: =AH3 -> 5.610668 | M2: no vacc | N2: constant vacc | O2: actual vacc | P2: opt vacc | R2: Type | S2: no vacc | T2: constant vacc | U2: actual vacc | V2: opt vacc | X2: Type | Y2: no vacc | Z2: constant vacc | AA2: actual vacc | AB2: opt vacc | AE2: no vacc | AF2: constant vacc | AG2: actual vacc | AH2: opt vacc | AK2: no vacc | AL2: constant vacc | AM2: actual vacc | AN2: opt vacc | AQ2: no vacc | AR2: constant vacc | AS2: actual vacc | AT2: opt vacc | BC2: opt vacc
A3: Policy Cost | B3: =P4 -> 3.574413 | C3: =V4 -> 3.796195 | E3: =AB4 -> 4.26938 | F3: =AH4 -> 4.513925 | L3: Hosp Cost | M3: 11.616842 | N3: 9.249465 | O3: 5.627283 | P3: 6.268083 | R3: 0 Hosp Cost | S3: 11.616842 | T3: 9.249465 | U3: 5.627283 | V3: 6.087827 | X3: 0 Hosp Cost | Y3: 11.616842 | Z3: 9.249465 | AA3: 5.627283 | AB3: 5.758631 | AE3: 11.616842 | AF3: 9.249465 | AG3: 6.374409 | AH3: 5.610668 | AK3: 11.616842 | AL3: 9.249465 | AM3: 6.374409 | AN3: 5.610668 | AQ3: 11.616842 | AR3: 9.249465 | AS3: 6.374409 | AT3: 5.610668 | AY3: Hosp Cost | AZ3: =M3 -> 11.616842 | BA3: =N3 -> 9.249465 | BB3: =O3 -> 5.627283 | BC3: =P3 -> 6.268083 | BD3: =V3 -> 6.087827 | BE3: =AB3 -> 5.758631 | BF3: =AH3 -> 5.610668
A4: Econ Cost | B4: =P5 -> 31.211228 | C4: =V5 -> 30.573665 | E4: =AB5 -> 29.429176 | F4: =AH5 -> 28.924867 | L4: Policy Cost | M4: 2.757488 | N4: 3.077856 | O4: 4.46062 | P4: 3.574413 | R4: 1 Policy Cost | S4: 2.757488 | T4: 3.077856 | U4: 4.46062 | V4: 3.796195 | X4: 1 Policy Cost | Y4: 2.757488 | Z4: 3.077856 | AA4: 4.46062 | AB4: 4.26938 | AE4: 2.757488 | AF4: 3.077856 | AG4: 3.979546 | AH4: 4.513925 | AK4: 2.757488 | AL4: 3.077856 | AM4: 3.979546 | AN4: 4.513925 | AQ4: 2.757488 | AR4: 3.077856 | AS4: 3.979546 | AT4: 4.513925 | AY4: Policy Cost | AZ4: =M4 -> 2.757488 | BA4: =N4 -> 3.077856 | BB4: =O4 -> 4.46062 | BC4: =P4 -> 3.574413 | BD4: =V4 -> 3.796195 | BE4: =AB4 -> 4.26938 | BF4: =AH4 -> 4.513925
A5: Total Cost | B5: =P6 -> 41.053725 | C5: =V6 -> 40.457688 | E5: =AB6 -> 39.457186 | F5: =AH6 -> 39.049459 | L5: Econ Cost | M5: 42.917935 | N5: 33.642296 | O5: 28.965808 | P5: 31.211228 | R5: 2 Econ Cost | S5: 42.917935 | T5: 33.642296 | U5: 28.965808 | V5: 30.573665 | X5: 2 Econ Cost | Y5: 42.917935 | Z5: 33.642296 | AA5: 28.965808 | AB5: 29.429176 | AE5: 42.917935 | AF5: 33.642296 | AG5: 31.83938 | AH5: 28.924867 | AK5: 42.917935 | AL5: 33.642296 | AM5: 31.83938 | AN5: 28.924867 | AQ5: 42.917935 | AR5: 33.642296 | AS5: 31.83938 | AT5: 28.924867 | AY5: Econ Cost | AZ5: =M5 -> 42.917935 | BA5: =N5 -> 33.642296 | BB5: =O5 -> 28.965808 | BC5: =P5 -> 31.211228 | BD5: =V5 -> 30.573665 | BE5: =AB5 -> 29.429176 | BF5: =AH5 -> 28.924867
L6: Total Cost | M6: 57.292265 | N6: 45.969617 | O6: 39.053711 | P6: 41.053725 | R6: 3 Total Cost | S6: 57.292265 | T6: 45.969617 | U6: 39.053711 | V6: 40.457688 | X6: 3 Total Cost | Y6: 57.292265 | Z6: 45.969617 | AA6: 39.053711 | AB6: 39.457186 | AE6: 57.292265 | AF6: 45.969617 | AG6: 42.193335 | AH6: 39.049459 | AK6: 57.292265 | AL6: 45.969617 | AM6: 42.193335 | AN6: 39.049459 | AQ6: 57.292265 | AR6: 45.969617 | AS6: 42.193335 | AT6: 39.049459 | AY6: Total Cost | AZ6: =M6 -> 57.292265 | BA6: =N6 -> 45.969617 | BB6: =O6 -> 39.053711 | BC6: =P6 -> 41.053725 | BD6: =V6 -> 40.457688 | BE6: =AB6 -> 39.457186 | BF6: =AH6 -> 39.049459
L8: Hosp Cost Savings | M8: =1-$P3/M3 -> 0.46043142 | N8: =1-$P3/N3 -> 0.32233021 | O8: =1-$P3/O3 -> -0.11387378 | S8: =1-$P3/S3 -> 0.46043142 | T8: =1-$P3/T3 -> 0.32233021 | U8: =1-$P3/U3 -> -0.11387378 | Y8: =1-$P3/Y3 -> 0.46043142 | Z8: =1-$P3/Z3 -> 0.32233021 | AA8: =1-$P3/AA3 -> -0.11387378 | AE8: =1-$AH3/AE3 -> 0.51702296 | AF8: =1-$AH3/AF3 -> 0.39340621 | AG8: =1-$AH3/AG3 -> 0.11981362 | AK8: =1-$AH3/AK3 -> 0.51702296 | AL8: =1-$AH3/AL3 -> 0.39340621 | AM8: =1-$AH3/AM3 -> 0.11981362 | AQ8: =1-$AH3/AQ3 -> 0.51702296 | AR8: =1-$AH3/AR3 -> 0.39340621 | AS8: =1-$AH3/AS3 -> 0.11981362
L9: Policy Cost Savings | M9: =1-$P4/M4 -> -0.29625696 | N9: =1-$P4/N4 -> -0.16133211 | O9: =1-$P4/O4 -> 0.1986735 | S9: =1-$P4/S4 -> -0.29625696 | T9: =1-$P4/T4 -> -0.16133211 | U9: =1-$P4/U4 -> 0.1986735 | Y9: =1-$P4/Y4 -> -0.29625696 | Z9: =1-$P4/Z4 -> -0.16133211 | AA9: =1-$P4/AA4 -> 0.1986735 | AE9: =1-$AH4/AE4 -> -0.63696995 | AF9: =1-$AH4/AF4 -> -0.46658096 | AG9: =1-$AH4/AG4 -> -0.1342814 | AK9: =1-$AH4/AK4 -> -0.63696995 | AL9: =1-$AH4/AL4 -> -0.46658096 | AM9: =1-$AH4/AM4 -> -0.1342814 | AQ9: =1-$AH4/AQ4 -> -0.63696995 | AR9: =1-$AH4/AR4 -> -0.46658096 | AS9: =1-$AH4/AS4 -> -0.1342814
L10: Econ Cost Savings | M10: =1-$P5/M5 -> 0.27276958 | N10: =1-$P5/N5 -> 0.07226225 | O10: =1-$P5/O5 -> -0.077519674 | S10: =1-$P5/S5 -> 0.27276958 | T10: =1-$P5/T5 -> 0.07226225 | U10: =1-$P5/U5 -> -0.077519674 | Y10: =1-$P5/Y5 -> 0.27276958 | Z10: =1-$P5/Z5 -> 0.07226225 | AA10: =1-$P5/AA5 -> -0.077519674 | AE10: =1-$AH5/AE5 -> 0.32604243 | AF10: =1-$AH5/AF5 -> 0.14022316 | AG10: =1-$AH5/AG5 -> 0.091537995 | AK10: =1-$AH5/AK5 -> 0.32604243 | AL10: =1-$AH5/AL5 -> 0.14022316 | AM10: =1-$AH5/AM5 -> 0.091537995 | AQ10: =1-$AH5/AQ5 -> 0.32604243 | AR10: =1-$AH5/AR5 -> 0.14022316 | AS10: =1-$AH5/AS5 -> 0.091537995
A11: diff | B11: 0.012 | C11: 0.0092 | E11: 0.0106 | F11: 0.0078 | L11: Total Cost Savings | M11: =1-$P6/M6 -> 0.28343337 | N11: =1-$P6/N6 -> 0.10693785 | O11: =1-$P6/O6 -> -0.051211881 | S11: =1-$P6/S6 -> 0.28343337 | T11: =1-$P6/T6 -> 0.10693785 | U11: =1-$P6/U6 -> -0.051211881 | Y11: =1-$P6/Y6 -> 0.28343337 | Z11: =1-$P6/Z6 -> 0.10693785 | AA11: =1-$P6/AA6 -> -0.051211881 | AE11: =1-$AH6/AE6 -> 0.31841656 | AF11: =1-$AH6/AF6 -> 0.15053765 | AG11: =1-$AH6/AG6 -> 0.074511199 | AK11: =1-$AH6/AK6 -> 0.31841656 | AL11: =1-$AH6/AL6 -> 0.15053765 | AM11: =1-$AH6/AM6 -> 0.074511199 | AQ11: =1-$AH6/AQ6 -> 0.31841656 | AR11: =1-$AH6/AR6 -> 0.15053765 | AS11: =1-$AH6/AS6 -> 0.074511199
A12: mid | B12: 0.016 | C12: 0.0132 | E12: 0.0146 | F12: 0.0118 | L12: new6 | R12: new4 | X12: new5 | AD12: new1 | AJ12: new1 | AP12: new1
B13: min-max*70% | C13: min-max*80% | D13: min-max*85% | E13: min-max*90% | F13: min-max (base) | G13: min-max*115% | L13: min-max*70% | R13: min-max*80% | X13: min-max*90% | AD13: min-max (base) | AJ13: min-max 0.85 | AP13: min-max 1.15
B14: =AVERAGE(L14:P14) -> 0.0198651 | C14: =AVERAGE(R14:V14) -> 0.0218458 | D14: =AVERAGE(AJ14:AN14) -> 0.02383136 | E14: =AVERAGE(X14:AB14) -> 0.0258058 | F14: =AVERAGE(AD14:AH14) -> 0.02778504 | G14: =AVERAGE(AP14:AT14) -> 0.0317465 | H14: =ROUND(E14,4)&"," -> 0.0258, | L14: 0.0198709 | M14: 0.0198553 | N14: 0.0198696 | O14: 0.0198619 | P14: 0.0198678 | R14: 0.0218525 | S14: 0.0218344 | T14: 0.021851 | U14: 0.0218421 | V14: 0.021849 | X14: 0.0258143 | Y14: 0.0257911 | Z14: 0.0258124 | AA14: 0.0258011 | AB14: 0.0258101 | AD14: 0.0277946 | AE14: 0.0277686 | AF14: 0.0277924 | AG14: 0.0277797 | AH14: 0.0277899 | AJ14: 0.0238206 | AK14: 0.0238331 | AL14: 0.0238252 | AM14: 0.0238204 | AN14: 0.0238575 | AP14: 0.0317299 | AQ14: 0.0317495 | AR14: 0.0317367 | AS14: 0.0317294 | AT14: 0.031787
B15: =AVERAGE(L15:P15) -> 0.01986832 | C15: =AVERAGE(R15:V15) -> 0.02184908 | D15: =AVERAGE(AJ15:AN15) -> 0.02383718 | E15: =AVERAGE(X15:AB15) -> 0.02580882 | F15: =AVERAGE(AD15:AH15) -> 0.02778774 | G15: =AVERAGE(AP15:AT15) -> 0.03175088 | H15: =ROUND(E15,4)&"," -> 0.0258, | L15: 0.0198745 | M15: 0.0198556 | N15: 0.0198763 | O15: 0.019864 | P15: 0.0198712 | R15: 0.0218563 | S15: 0.0218343 | T15: 0.0218582 | U15: 0.0218441 | V15: 0.0218525 | X15: 0.0258182 | Y15: 0.0257898 | Z15: 0.0258202 | AA15: 0.0258026 | AB15: 0.0258133 | AD15: 0.0277982 | AE15: 0.0277666 | AF15: 0.0278003 | AG15: 0.0277808 | AH15: 0.0277928 | AJ15: 0.0238228 | AK15: 0.0238355 | AL15: 0.0238365 | AM15: 0.0238363 | AN15: 0.0238548 | AP15: 0.0317284 | AQ15: 0.0317487 | AR15: 0.031749 | AS15: 0.031748 | AT15: 0.0317803
B16: =AVERAGE(L16:P16) -> 0.01986366 | C16: =AVERAGE(R16:V16) -> 0.02184328 | D16: =AVERAGE(AJ16:AN16) -> 0.02382668 | E16: =AVERAGE(X16:AB16) -> 0.02580032 | F16: =AVERAGE(AD16:AH16) -> 0.02777764 | G16: =AVERAGE(AP16:AT16) -> 0.0317303 | H16: =ROUND(E16,4)&"," -> 0.0258, | L16: 0.0198685 | M16: 0.019852 | N16: 0.0198724 | O16: 0.0198598 | P16: 0.0198656 | R16: 0.021849 | S16: 0.0218297 | T16: 0.0218532 | U16: 0.0218388 | V16: 0.0218457 | X16: 0.025808 | Y16: 0.0257825 | Z16: 0.0258126 | AA16: 0.0257948 | AB16: 0.0258037 | AD16: 0.0277864 | AE16: 0.0277577 | AF16: 0.0277911 | AG16: 0.0277714 | AH16: 0.0277816 | AJ16: 0.0238123 | AK16: 0.0238251 | AL16: 0.023826 | AM16: 0.0238225 | AN16: 0.0238475 | AP16: 0.0317082 | AQ16: 0.031729 | AR16: 0.031727 | AS16: 0.0317227 | AT16: 0.0317646
