Workbook
Name Full: #REF!
Name Glossary: #REF!
Name scope: #REF!
Name TopOfTable_Table_2: #REF!
Name TopOfTable_Table_2: death_vic!$A$2
Name Y2015_BIRTHS_LG: birth_vic!$A$6:$B$88

Sheet reg control (2)
K1: top | L1: bottom
C2: top | K2: k0 = 0.0067 | L2: k0 = 0.0053 | N2: k0 low 0.0053 | O2: k0 high 0.0067 | S2: Strategy 1 | T2: Strategy 2 | U2: Optimal Control
C3: k0 = 0.0067 | F3: vaccination_rate | I3: bottom | K3: k1 = -0.1006 | L3: k1 = -0.1676 | M3: avg | N3: k1 high -0.1006 | O3: k1 low -0.1676 | S3: Constant Vaccination | T3: Actual alpha | U3: control_1 | V3: control_2 | W3: control_3 | X3: control_4 | Y3: control_5 | AB3: avg over rounds
C4: k1 = -0.1006 | F4: 0.02779241 | I4: k0 = 0.0053 | J4: 1 | K4: =F4 -> 0.02779241 | L4: 0.02779236 | M4: =AB4 -> 0.02447724 | N4: 0.02779235 | O4: 0.02779241 | S4: =$F$3 -> vaccination_rate | T4: =Reg_30days!AJ32 -> 0 | U4: 0.0245031 | V4: 0.0244278 | W4: 0.0244835 | X4: 0.0244886 | Y4: 0.0244832 | AB4: =AVERAGE(U4:Y4) -> 0.02447724
F5: 0.02779357 | I5: k1 = -0.1676 | J5: 2 | K5: =F5 -> 0.02779357 | L5: 0.02779371 | M5: =AB5 -> 0.02438572 | N5: 0.02779351 | O5: 0.02779376 | S5: =$F$3 -> vaccination_rate | T5: =Reg_30days!AJ33 -> 0 | U5: 0.0244224 | V5: 0.0243765 | W5: 0.0243693 | X5: 0.0243777 | Y5: 0.0243827 | AB5: =AVERAGE(U5:Y5) -> 0.02438572
F6: 0.02777892 | J6: 3 | K6: =F6 -> 0.02777892 | L6: 0.02777925 | M6: =AB6 -> 0.0242678 | N6: 0.02777886 | O6: 0.0277793 | S6: =$F$3 -> vaccination_rate | T6: =Reg_30days!AJ34 -> 0 | U6: 0.0243032 | V6: 0.0242313 | W6: 0.0242684 | X6: 0.0242707 | Y6: 0.0242654 | AB6: =AVERAGE(U6:Y6) -> 0.0242678
F7: 0.02776494 | J7: 4 | K7: =F7 -> 0.02776494 | L7: 0.02776547 | M7: =AB7 -> 0.02410956 | N7: 0.02776487 | O7: 0.02776553 | S7: =$F$3 -> vaccination_rate | T7: =Reg_30days!AJ35 -> 0 | U7: 0.0241285 | V7: 0.0241053 | W7: 0.0240692 | X7: 0.024107 | Y7: 0.0241378 | AB7: =AVERAGE(U7:Y7) -> 0.02410956
F8: 0.02774444 | J8: 5 | K8: =F8 -> 0.02774444 | L8: 0.02774524 | M8: =AB8 -> 0.02387136 | N8: 0.02774436 | O8: 0.0277453 | S8: =$F$3 -> vaccination_rate | T8: =Reg_30days!AJ36 -> 0 | U8: 0.02399 | V8: 0.0237615 | W8: 0.0239481 | X8: 0.0239716 | Y8: 0.0236856 | AB8: =AVERAGE(U8:Y8) -> 0.02387136
F9: 0.02771779 | J9: 6 | K9: =F9 -> 0.02771779 | L9: 0.02771905 | M9: =AB9 -> 0.02355274 | N9: 0.02771771 | O9: 0.02771912 | S9: =$F$3 -> vaccination_rate | T9: =Reg_30days!AJ37 -> 0 | U9: 0.0239124 | V9: 0.023483 | W9: 0.0234279 | X9: 0.0233801 | Y9: 0.0235603 | AB9: =AVERAGE(U9:Y9) -> 0.02355274
F10: 0.02769106 | J10: 7 | K10: =F10 -> 0.02769106 | L10: 0.02769274 | M10: =AB10 -> 0.02338316 | N10: 0.02769097 | O10: 0.0276928 | S10: =$F$3 -> vaccination_rate | T10: =Reg_30days!AJ38 -> 0 | U10: 0.0235616 | V10: 0.0234558 | W10: 0.0234109 | X10: 0.0231867 | Y10: 0.0233008 | AB10: =AVERAGE(U10:Y10) -> 0.02338316
F11: 0.02765664 | J11: 8 | K11: =F11 -> 0.02765664 | L11: 0.02765901 | M11: =AB11 -> 0.02316708 | N11: 0.02765656 | O11: 0.02765907 | S11: =$F$3 -> vaccination_rate | T11: =Reg_30days!AJ39 -> 0 | U11: 0.0231953 | V11: 0.0231481 | W11: 0.02331 | X11: 0.0231032 | Y11: 0.0230788 | AB11: =AVERAGE(U11:Y11) -> 0.02316708
F12: 0.02761797 | J12: 9 | K12: =F12 -> 0.02761797 | L12: 0.02762101 | M12: =AB12 -> 0.02305654 | N12: 0.02761784 | O12: 0.0276211 | S12: =$F$3 -> vaccination_rate | T12: =Reg_30days!AJ40 -> 0 | U12: 0.0230804 | V12: 0.0229861 | W12: 0.0233851 | X12: 0.0229123 | Y12: 0.0229188 | AB12: =AVERAGE(U12:Y12) -> 0.02305654
F13: 0.02759025 | J13: 10 | K13: =F13 -> 0.02759025 | L13: 0.02759398 | M13: =AB13 -> 0.02285692 | N13: 0.02759015 | O13: 0.02759403 | S13: =$F$3 -> vaccination_rate | T13: =Reg_30days!AJ41 -> 0 | U13: 0.022797 | V13: 0.0226103 | W13: 0.0232388 | X13: 0.0229475 | Y13: 0.022691 | AB13: =AVERAGE(U13:Y13) -> 0.02285692
F14: 0.02758413 | J14: 11 | K14: =F14 -> 0.02758413 | L14: 0.02758989 | M14: =AB14 -> 0.02267136 | N14: 0.02758616 | O14: 0.02758931 | S14: =$F$3 -> vaccination_rate | T14: =Reg_30days!AJ42 -> 0 | U14: 0.0225398 | V14: 0.0225778 | W14: 0.0229953 | X14: 0.0226186 | Y14: 0.0226253 | AB14: =AVERAGE(U14:Y14) -> 0.02267136
F15: 0.02747588 | J15: 12 | K15: =F15 -> 0.02747588 | L15: 0.02748173 | M15: =AB15 -> 0.02247434 | N15: 0.02747582 | O15: 0.02748176 | S15: =$F$3 -> vaccination_rate | T15: =Reg_30days!AJ43 -> 0 | U15: 0.0223361 | V15: 0.0225738 | W15: 0.022726 | X15: 0.0224946 | Y15: 0.0222412 | AB15: =AVERAGE(U15:Y15) -> 0.02247434
F16: 0.02734684 | J16: 13 | K16: =F16 -> 0.02734684 | L16: 0.02735633 | M16: =AB16 -> 0.02239424 | N16: 0.02734733 | O16: 0.027356 | S16: =$F$3 -> vaccination_rate | T16: =Reg_30days!AJ44 -> 0 | U16: 0.0221573 | V16: 0.0222858 | W16: 0.0225789 | X16: 0.0226736 | Y16: 0.0222756 | AB16: =AVERAGE(U16:Y16) -> 0.02239424
F17: 0.02724283 | J17: 14 | K17: =F17 -> 0.02724283 | L17: 0.0272533 | M17: =AB17 -> 0.02230826 | N17: 0.02724293 | O17: 0.02725343 | S17: =$F$3 -> vaccination_rate | T17: =Reg_30days!AJ45 -> 0 | U17: 0.0226141 | V17: 0.0222929 | W17: 0.0225579 | X17: 0.0223482 | Y17: 0.0217282 | AB17: =AVERAGE(U17:Y17) -> 0.02230826
... F63: 0.00424856 | J63: 60 | K63: =F63 -> 0.00424856 | L63: 0.00424851 | M63: =AB63 -> 0.005159404 | N63: 0.00424854 | O63: 0.00424854 | S63: =$F$3 -> vaccination_rate | T63: =Reg_30days!AJ91 -> 0 | U63: 0.00516643 | V63: 0.00515081 | W63: 0.00516471 | X63: 0.00515668 | Y63: 0.00515839 | AB63: =AVERAGE(U63:Y63) -> 0.005159404
S70: upper
E71: lower | AE71: base | AQ71: k1low | BC71: k0 low
AQ72: k0 high | BC72: k1 high
G84: Strategy | H84: Total Cost | I84: Healthcare | J84: Policy | K84: Economic | L84: Cost reduction
G85: No Vaccination | H85: 38.72 | I85: 9.5 | J85: 1.66 | K85: 27.56 | L85: =1-H88/H85 -> 0.17742769
G86: Constant Vaccination | H86: 34.28 | I86: 8.13 | J86: 3.08 | K86: 23.07 | L86: =1-H88/H86 -> 0.070886814
G87: Actual (Government) | H87: 31.4 | I87: 4.93 | J87: 3.35 | K87: 23.12
G88: Optimal | H88: 31.85 | I88: 4.42 | J88: 5.89 | K88: 21.54
E101: standard
E111: peak infected | F111: hosp | G111: icu
D112: no | AQ112: Strategy | AR112: Peak Infected | AS112: Peak Mild | AT112: Peak Hosp | AU112: Peak ICU | AV112: Peak Infected | AW112: Peak Mild | AX112: Peak Hosp | AY112: Peak ICU | BC112: Strategy | BD112: Peak Infected | BE112: Peak Mild | BF112: Peak Hosp | BG112: Peak ICU | BH112: Peak Infected | BI112: Peak Mild | BJ112: Peak Hosp | BK112: Peak ICU
D113: constant | AQ113: No Vaccination | AR113: 0.5662 | AS113: 0.5421 | AT113: 0.02185 | AU113: 0.01598 | AV113: =1-AR116/AR113 -> 0.0060049452 | AW113: =1-AS116/AS113 -> -0.027116768 | AX113: =1-AT116/AT113 -> 0.65629291 | AY113: =1-AU116/AU113 -> 0.8097622 | BC113: No Vaccination | BD113: 0.5662 | BE113: 0.5421 | BF113: 0.02185 | BG113: 0.01598 | BH113: =1-BD116/BD113 -> 0.0060049452 | BI113: =1-BE116/BE113 -> -0.026194429 | BJ113: =1-BF116/BF113 -> 0.65629291 | BK113: =1-BG116/BG113 -> 0.79411765
D114: optimal | S114: Strategy | T114: Peak Infected | U114: Peak Mild | V114: Peak Hosp | W114: Peak ICU | X114: Peak Infected | Y114: Peak Mild | Z114: Peak Hosp | AA114: Peak ICU | AQ114: Constant Vaccination | AR114: 0.5632 | AS114: 0.5395 | AT114: 0.02161 | AU114: 0.01551 | AV114: =1-AR116/AR114 -> 0.00071022727 | AW114: =1-AS116/AS114 -> -0.032066728 | AX114: =1-AT116/AT114 -> 0.65247571 | AY114: =1-AU116/AU114 -> 0.80399742 | BC114: Constant Vaccination | BD114: 0.5632 | BE114: 0.5395 | BF114: 0.02161 | BG114: 0.01551 | BH114: =1-BD116/BD114 -> 0.00071022727 | BI114: =1-BE116/BE114 -> -0.031139944 | BJ114: =1-BF116/BF114 -> 0.65247571 | BK114: =1-BG116/BG114 -> 0.78787879
F115: Strategy | G115: Peak Infected | H115: Peak Mild | I115: Peak Hosp | J115: Peak ICU | K115: Peak Infected | L115: Peak Mild | M115: Peak Hosp | N115: Peak ICU | S115: No Vaccination | T115: 0.5662 | U115: 0.5421 | V115: 0.02185 | W115: 0.01598 | X115: =1-T118/T115 -> 0.0061815613 | Y115: =1-U118/U115 -> -0.023058476 | Z115: =1-V118/V115 -> 0.65583524 | AA115: =1-W118/W115 -> 0.73404255 | AE115: Strategy | AF115: Peak Infected | AG115: Peak Mild | AH115: Peak Hosp | AI115: Peak ICU | AJ115: Peak Infected | AK115: Peak Mild | AL115: Peak Hosp | AM115: Peak ICU | AQ115: Actual (Government) | AR115: 0.5649 | AS115: 0.5564 | AT115: 0.00752 | AU115: 0.0043 | BC115: Actual (Government) | BD115: 0.5649 | BE115: 0.5569 | BF115: 0.00752 | BG115: 0.00408
F116: No Vaccination | G116: 0.5662 | H116: 0.5421 | I116: 0.02185 | J116: 0.01598 | K116: =1-G119/G116 -> 0.0058283292 | L116: =1-H119/H116 -> -0.02951485 | M116: =1-I119/I116 -> 0.65629291 | N116: =1-J119/J116 -> 0.83291615 | S116: Constant Vaccination | T116: 0.5632 | U116: 0.5395 | V116: 0.02161 | W116: 0.01551 | X116: =1-T118/T116 -> 0.00088778409 | Y116: =1-U118/U116 -> -0.027988879 | Z116: =1-V118/V116 -> 0.65201296 | AA116: =1-W118/W116 -> 0.72598324 | AE116: No Vaccination | AF116: 0.5662 | AG116: 0.5421 | AH116: 0.02185 | AI116: 0.01598 | AJ116: =1-AF119/AF116 -> 0.0060049452 | AK116: =1-AG119/AG116 -> -0.026563365 | AL116: =1-AH119/AH116 -> 0.65629291 | AM116: =1-AI119/AI116 -> 0.80162703 | AQ116: Optimal | AR116: 0.5628 | AS116: 0.5568 | AT116: 0.00751 | AU116: 0.00304 | BC116: Optimal | BD116: 0.5628 | BE116: 0.5563 | BF116: 0.00751 | BG116: 0.00329
F117: Constant Vaccination | G117: 0.5632 | H117: 0.5395 | I117: 0.02161 | J117: 0.01551 | K117: =1-G119/G117 -> 0.00053267045 | L117: =1-H119/H117 -> -0.034476367 | M117: =1-I119/I117 -> 0.65247571 | N117: =1-J119/J117 -> 0.827853 | S117: Actual (Government) | T117: 0.5648 | U117: 0.5552 | V117: 0.00757 | W117: 0.00512 | AE117: Constant Vaccination | AF117: 0.5632 | AG117: 0.5395 | AH117: 0.02161 | AI117: 0.01551 | AJ117: =1-AF119/AF117 -> 0.00071022727 | AK117: =1-AG119/AG117 -> -0.031510658 | AL117: =1-AH119/AH117 -> 0.65247571 | AM117: =1-AI119/AI117 -> 0.79561573
F118: Actual (Government) | G118: 0.565 | H118: 0.5581 | I118: 0.00751 | J118: 0.0034 | S118: Optimal | T118: 0.5627 | U118: 0.5546 | V118: 0.00752 | W118: 0.00425 | AE118: Actual (Government) | AF118: 0.5649 | AG118: 0.5567 | AH118: 0.00752 | AI118: 0.00419
F119: Optimal | G119: 0.5629 | H119: 0.5581 | I119: 0.00751 | J119: 0.00267 | AE119: Optimal | AF119: 0.5628 | AG119: 0.5565 | AH119: 0.00751 | AI119: 0.00317 | AQ119: Table 3: Peak Infection (Mean, absolute numbers) | BC119: Table 3: Peak Infection (Mean, absolute numbers)
F121: Strategy | G121: Peak Infected | H121: Peak Mild | I121: Peak Hosp | J121: Peak ICU | K121: Peak Infected | L121: Peak Mild | M121: Peak Hosp | N121: Peak ICU | AQ121: Strategy | AR121: Peak Infected | AS121: Peak Mild | AT121: Peak Hosp | AU121: Peak ICU | BC121: Strategy | BD121: Peak Infected | BE121: Peak Mild | BF121: Peak Hosp | BG121: Peak ICU
F122: No Vaccination | G122: 37539 | H122: 35941 | I122: 1448 | J122: 1059 | K122: =1-G125/G122 -> 0.0058072937 | L122: =1-H125/H122 -> -0.029437133 | M122: =1-I125/I122 -> 0.65607735 | N122: =1-J125/J122 -> 0.83286119 | AE122: Table 3: Peak Infection (Mean, absolute numbers) | AQ122: No Vaccination | AR122: 37539 | AS122: 35941 | AT122: 1448 | AU122: 1059 | BC122: No Vaccination | BD122: 37539 | BE122: 35941 | BF122: 1448 | BG122: 1059
F123: Constant Vaccination | G123: 37338 | H123: 35769 | I123: 1433 | J123: 1028 | K123: =1-G125/G123 -> 0.00045530023 | L123: =1-H125/H123 -> -0.034387319 | M123: =1-I125/I123 -> 0.65247732 | N123: =1-J125/J123 -> 0.82782101 | S123: Strategy | T123: Peak Infected | U123: Peak Mild | V123: Peak Hosp | W123: Peak ICU | AQ123: Constant Vaccination | AR123: 37338 | AS123: 35769 | AT123: 1433 | AU123: 1028 | BC123: Constant Vaccination | BD123: 37338 | BE123: 35769 | BF123: 1433 | BG123: 1028
F124: Actual (Government) | G124: 37460 | H124: 37002 | I124: 498 | J124: 225 | S124: No Vaccination | T124: 37539 | U124: 35941 | V124: 1448 | W124: 1059 | AE124: Strategy | AF124: Peak Infected | AG124: Peak Mild | AH124: Peak Hosp | AI124: Peak ICU | AQ124: Actual (Government) | AR124: 37452 | AS124: 36889 | AT124: 498 | AU124: 285 | BC124: Actual (Government) | BD124: 37454 | BE124: 36923 | BF124: 498 | BG124: 271
...

Sheet net_migration
B1: Overseas migrant arrivals and departures by visa group by state, quarterly and financial years, from September quarter 2006 onwards
B2: Frequency: Quarterly
B4: Time Period | C4: Time Period | D4: 2020-Q1 | E4: 2020-Q2 | F4: 2020-Q3 | G4: 2020-Q4 | H4: 2021-Q1 | I4: 2021-Q2 | J4: 2021-Q3 | K4: 2021-Q4 | L4: 2022-Q1 | M4: 2022-Q2 | N4: 2022-Q3 | O4: 2022-Q4 | P4: 2023-Q1 | Q4: 2023-Q2 | R4: 2023-Q3 | S4: 2023-Q4
B5: Visa and Citizenship Groups
B6: Migration Type: Migrant arrivals
B7: Region: Victoria
B8: Unit of measure: Persons
B9: Total | D9: 48160 | E9: 3080 | F9: 2500 | G9: 6010 | H9: 8850 | I9: 9790 | J9: 9330 | K9: 30680 | L9: 50970 | M9: 38330 | N9: 51700 | O9: 49780 | P9: 63040 | Q9: 48530 | R9: 56890 | S9: 46880
B10: · Permanent visa - Total | D10: 6250 | E10: 1060 | F10: 650 | G10: 1720 | H10: 2910 | I10: 3720 | J10: 3260 | K10: 7310 | L10: 6520 | M10: 6020 | N10: 5670 | O10: 6380 | P10: 6530 | Q10: 6900 | R10: 6310 | S10: 7660
B11: · · Permanent visa - Family | D11: 2000 | E11: 400 | F11: 260 | G11: 750 | H11: 1190 | I11: 1720 | J11: 1250 | K11: 2820 | L11: 2200 | M11: 1770 | N11: 1600 | O11: 1890 | P11: 1600 | Q11: 1790 | R11: 1710 | S11: 2600
B12: · · Permanent visa - Skill | D12: 2470 | E12: 500 | F12: 250 | G12: 700 | H12: 1250 | I12: 1430 | J12: 1310 | K12: 2850 | L12: 2800 | M12: 2300 | N12: 2340 | O12: 2250 | P12: 3000 | Q12: 3000 | R12: 2670 | S12: 2800
B13: · · Permanent visa - Special eligibility and humanitarian | D13: 980 | E13: 0 | F13: 0 | G13: 30 | H13: 40 | I13: 80 | J13: 330 | K13: 790 | L13: 610 | M13: 1020 | N13: 880 | O13: 1320 | P13: 930 | Q13: 1290 | R13: 1180 | S13: 1440
B14: · · Permanent visa - Other permanent visas | D14: 790 | E14: 160 | F14: 130 | G14: 240 | H14: 430 | I14: 500 | J14: 370 | K14: 850 | L14: 920 | M14: 930 | N14: 850 | O14: 920 | P14: 990 | Q14: 820 | R14: 750 | S14: 820
B15: · Temporary visa - Total | D15: 33360 | E15: 320 | F15: 370 | G15: 910 | H15: 1390 | I15: 1720 | J15: 2430 | K15: 16660 | L15: 37120 | M15: 26190 | N15: 39390 | O15: 35570 | P15: 48710 | Q15: 35670 | R15: 43780 | S15: 30930
B16: · · Temporary visa - Student | D16: 14050 | E16: 0 | F16: 0 | G16: 40 | H16: 110 | I16: 150 | J16: 200 | K16: 10500 | L16: 25590 | M16: 10460 | N16: 21850 | O16: 14210 | P16: 28760 | Q16: 15560 | R16: 23730 | S16: 9400
B17: · · · Temporary visa - Student -Vocational education and training sector | D17: 730 | E17: 0 | F17: 0 | G17: 0 | H17: 10 | I17: 10 | J17: 10 | K17: 1350 | L17: 2090 | M17: 1650 | N17: 2320 | O17: 2380 | P17: 2400 | Q17: 2920 | R17: 2670 | S17: 1270
B18: · · · Temporary visa -Student - Higher education sector | D18: 10690 | E18: 0 | F18: 0 | G18: 20 | H18: 70 | I18: 70 | J18: 80 | K18: 8200 | L18: 20610 | M18: 6120 | N18: 14900 | O18: 7280 | P18: 21320 | Q18: 8130 | R18: 16690 | S18: 5630
B19: · · · Temporary visa - student - Other temporary student visas | D19: 2630 | E19: 0 | F19: 0 | G19: 10 | H19: 40 | I19: 80 | J19: 110 | K19: 950 | L19: 2880 | M19: 2690 | N19: 4630 | O19: 4540 | P19: 5040 | Q19: 4510 | R19: 4370 | S19: 2500
B20: · · Temporary visa - Temporary work (skilled) | D20: 1760 | E20: 40 | F20: 100 | G20: 290 | H20: 510 | I20: 490 | J20: 560 | K20: 1430 | L20: 2010 | M20: 2320 | N20: 2960 | O20: 3630 | P20: 3870 | Q20: 3320 | R20: 3530 | S20: 2850
... B26: · Other Visas | D26: 140 | E26: 10 | F26: 10 | G26: 20 | H26: 30 | I26: 30 | J26: 360 | K26: 110 | L26: 60 | M26: 60 | N26: 100 | O26: 0 | P26: 0 | Q26: 0 | R26: 0 | S26: 0
B27: Migration Type: Migrant departures
B28: Region: Victoria
B29: Unit of measure: Persons
B30: Total | D30: 26750 | E30: 5590 | F30: 23100 | G30: 24690 | H30: 18730 | I30: 13620 | J30: 14270 | K30: 17580 | L30: 15590 | M30: 15820 | N30: 14130 | O30: 12190 | P30: 13260 | Q30: 13250 | R30: 13730 | S30: 14920
B31: · Permanent visa - Total | D31: 2470 | E31: 240 | F31: 1510 | G31: 2280 | H31: 1710 | I31: 1530 | J31: 1620 | K31: 2360 | L31: 1720 | M31: 1670 | N31: 1340 | O31: 1390 | P31: 1620 | Q31: 1540 | R31: 1440 | S31: 1590
B32: · · Permanent visa - Family | D32: 660 | E32: 60 | F32: 320 | G32: 420 | H32: 360 | I32: 400 | J32: 380 | K32: 560 | L32: 440 | M32: 480 | N32: 370 | O32: 340 | P32: 460 | Q32: 430 | R32: 380 | S32: 370
B33: · · Permanent visa - Skill | D33: 920 | E33: 90 | F33: 660 | G33: 1030 | H33: 650 | I33: 540 | J33: 620 | K33: 740 | L33: 430 | M33: 460 | N33: 330 | O33: 400 | P33: 340 | Q33: 330 | R33: 310 | S33: 440
B34: · · Permanent visa - Special eligibility and humanitarian | D34: 10 | E34: 0 | F34: 0 | G34: 10 | H34: 10 | I34: 0 | J34: 10 | K34: 10 | L34: 10 | M34: 10 | N34: 10 | O34: 10 | P34: 10 | Q34: 10 | R34: 20 | S34: 10
B35: · · Permanent visa - Other permanent visas | D35: 880 | E35: 90 | F35: 520 | G35: 830 | H35: 700 | I35: 590 | J35: 630 | K35: 1050 | L35: 830 | M35: 730 | N35: 630 | O35: 640 | P35: 810 | Q35: 770 | R35: 730 | S35: 760
B36: · Temporary visa - Total | D36: 17860 | E36: 4440 | F36: 16520 | G36: 16800 | H36: 13290 | I36: 7980 | J36: 7860 | K36: 9170 | L36: 7410 | M36: 5960 | N36: 5360 | O36: 4860 | P36: 5610 | Q36: 5020 | R36: 5540 | S36: 7220
B37: · · Temporary visa - Student | D37: 8100 | E37: 1740 | F37: 9180 | G37: 9120 | H37: 4490 | I37: 1880 | J37: 2680 | K37: 2880 | L37: 1840 | M37: 870 | N37: 970 | O37: 1030 | P37: 1280 | Q37: 1060 | R37: 1880 | S37: 2760
B38: · · · Temporary visa - Student -Vocational education and training sector | D38: 2140 | E38: 810 | F38: 1510 | G38: 970 | H38: 710 | I38: 480 | J38: 510 | K38: 540 | L38: 460 | M38: 400 | N38: 310 | O38: 260 | P38: 350 | Q38: 260 | R38: 350 | S38: 410
B39: · · · Temporary visa -Student - Higher education sector | D39: 5190 | E39: 670 | F39: 6930 | G39: 7060 | H39: 3240 | I39: 1160 | J39: 1790 | K39: 1870 | L39: 1170 | M39: 320 | N39: 520 | O39: 600 | P39: 710 | Q39: 580 | R39: 1110 | S39: 1840
B40: · · · Temporary visa - student - Other temporary student visas | D40: 780 | E40: 260 | F40: 750 | G40: 1100 | H40: 540 | I40: 240 | J40: 380 | K40: 470 | L40: 210 | M40: 150 | N40: 140 | O40: 170 | P40: 220 | Q40: 220 | R40: 420 | S40: 500
B41: · · Temporary visa - Temporary work (skilled) | D41: 1100 | E41: 370 | F41: 990 | G41: 880 | H41: 750 | I41: 710 | J41: 590 | K41: 690 | L41: 420 | M41: 540 | N41: 360 | O41: 280 | P41: 270 | Q41: 340 | R41: 290 | S41: 370
... B47: · Other Visas | D47: 230 | E47: 60 | F47: 160 | G47: 440 | H47: 100 | I47: 110 | J47: 300 | K47: 370 | L47: 240 | M47: 330 | N47: 540 | O47: 0 | P47: 0 | Q47: 0 | R47: 0 | S47: 0
D48: =D9-D30 -> 21410 | E48: =E9-E30 -> -2510 | F48: =F9-F30 -> -20600 | G48: =G9-G30 -> -18680 | H48: =H9-H30 -> -9880 | I48: =I9-I30 -> -3830 | J48: =J9-J30 -> -4940 | K48: =K9-K30 -> 13100 | ... S48: =S9-S30 -> 31960 | V48: https://explore.data.abs.gov.au/vis?fs[0]=People%2C1%7CPopulation%23POPULATION%23%7COverseas%20Migration%23OVERSEAS_MIGRATION%23&pg=0&fc=People&df[ds]=PEOPLE_TOPICS&df[id]=OMAD_VISA&df[ag]=ABS&df[vs]=&pd=2020-Q1%2C&dq=..2%2BAUS.Q&ly[cl]=TIME_PERIOD&ly[rw]=VISA&ly[rs]=MEASURE
K50: N | L50: annual data | M50: annual rate | N50: daily data | O50: daily rate | P50: daily rate | S50: [S4] Spain | T50: fertilty rate of spain = 1.2, au=1.6
I51: 2021 | J51: migration | N51: =K48/(31+30+31) -> 142.3913 | O51: =N51/K52 -> 2.1745638e-05 | V51: https://www.abs.gov.au/statistics/people/population/births-australia/2022
J52: birth | K52: 6548040 | L52: 75363 | M52: =L52/K52 -> 0.011509246 | N52: =L52/365 -> 206.47397 | O52: =N52/K52 -> 3.1532179e-05 | P52: =(N52+N51)/K52 -> 5.3277817e-05 | S52: =1165/47431256 -> 2.4561863e-05 | T52: =S52/1.2*1.6 -> 3.274915e-05 | V52: https://www.abs.gov.au/statistics/people/population/deaths-australia/2022
...

Sheet Sheet1
B3: Monte Carlo Simulation Results
B5: Outcome Metric | C5: No Vacc | D5: Constant | E5: Actual | F5: Optimal | G5: Actual vs No | H5: Optimal vs No | I5: Actual vs No | J5: Optimal vs No
B6: Epidemiological outcomes
B7: Peak infection prevalence (%) | C7: 0.566 | D7: 0.563 | E7: 0.565 | F7: 0.563 | G7: -0.2% | H7: -0.6% | I7: =E7/C7-1 -> -0.0017667845 | J7: =F7/C7-1 -> -0.0053003534 | K7: =J7-I7 -> -0.0035335689
B8: Peak hospitalised (persons) | C8: 1448 | D8: 1433 | E8: 498 | F8: 498 | G8: -65.6% | H8: -65.6% | I8: =E8/C8-1 -> -0.65607735 | J8: =F8/C8-1 -> -0.65607735 | K8: =J8-I8 -> 0
B9: Peak ICU (persons) | C9: 1059 | D9: 1028 | E9: 278 | F9: 210 | G9: -73.8% | H9: -80.2% | I9: =E9/C9-1 -> -0.7374882 | J9: =F9/C9-1 -> -0.80169972 | K9: =J9-I9 -> -0.06421152
B10: Cumulative hospital-days | C10: 27456 | D10: 23439 | E10: 5450 | F10: 4042 | G10: -80.2% | H10: -85.3% | I10: =E10/C10-1 -> -0.80150058 | J10: =F10/C10-1 -> -0.85278263 | K10: =J10-I10 -> -0.051282051
B11: Cumulative ICU-days | C11: 27063 | D11: 23496 | E11: 6031 | F11: 4663 | G11: -77.7% | H11: -82.8% | I11: =E11/C11-1 -> -0.77714961 | J11: =F11/C11-1 -> -0.82769833 | K11: =J11-I11 -> -0.05054872
B12: Cumulative deaths | C12: 110.9 | D12: 96 | E12: 23 | F12: 17.3 | G12: -79.3% | H12: -84.4% | I12: =E12/C12-1 -> -0.79260595 | J12: =F12/C12-1 -> -0.84400361 | K12: =J12-I12 -> -0.051397656
B13: Cost outcomes (units)
B14: Vaccination costs | C14: 0 | D14: 1.71 | E14: 1.96 | F14: 2.45 | G14: – | H14: –
B15: Quarantine costs | C15: 1.66 | D15: 1.37 | E15: 1.39 | F15: 1.3 | G15: -16.3% | H15: -21.9% | I15: =E15/C15-1 -> -0.1626506 | J15: =F15/C15-1 -> -0.21686747 | K15: =J15-I15 -> -0.054216867
B16: Healthcare costs | C16: 9.5 | D16: 8.13 | E16: 5.21 | F16: 4.72 | G16: -45.2% | H16: -50.3% | I16: =E16/C16-1 -> -0.45157895 | J16: =F16/C16-1 -> -0.50315789 | K16: =J16-I16 -> -0.051578947
B17: Economic productivity loss | C17: 27.56 | D17: 23.07 | E17: 23.09 | F17: 21.62 | G17: -16.2% | H17: -21.6% | I17: =E17/C17-1 -> -0.16219158 | J17: =F17/C17-1 -> -0.21552975 | K17: =J17-I17 -> -0.053338171
B18: Total cost | C18: 38.72 | D18: 34.28 | E18: 31.65 | F18: 30.08 | G18: -18.3% | H18: -22.3% | I18: =E18/C18-1 -> -0.18259298 | J18: =F18/C18-1 -> -0.2231405 | K18: =J18-I18 -> -0.040547521

Sheet birth_vic
A1: Australian Bureau of Statistics
A2: =[1]Contents!A2 -> 33010DO003 Births, Australia, 2021
A3: =[1]Contents!A3 -> Released at 11.30am (Canberra time) Tuesday 25 October 2022
A4: Table 3.2 Births, Summary, Local Government Areas, Victoria–2011 to 2021
C6: 2011 | G6: 2012 | K6: 2013 | O6: 2014 | S6: 2015 | W6: 2016 | AA6: 2017 | AE6: 2018 | AI6: 2019 | AM6: 2020 | AQ6: 2021
A7: Local government area of usual address | C7: Estimated resident population | D7: Births | E7: Total fertility rate | G7: Estimated resident population | H7: Births | I7: Total fertility rate | K7: Estimated resident population | L7: Births | M7: Total fertility rate | O7: Estimated resident population | P7: Births | Q7: Total fertility rate | S7: Estimated resident population | T7: Births | U7: Total fertility rate | W7: Estimated resident population | X7: Births | Y7: Total fertility rate | AA7: Estimated resident population | AB7: Births | AC7: Total fertility rate | AE7: Estimated resident population | AF7: Births | AG7: Total fertility rate | AI7: Estimated resident population | AJ7: Births | AK7: Total fertility rate | AM7: Estimated resident population | AN7: Births | AO7: Total fertility rate | AQ7: Estimated resident population | AR7: Births | AS7: Total fertility rate
A8: LGA Code 2021 | B8: LGA Name 2021 | C8: persons | D8: no. | E8: rate | G8: persons | H8: no. | I8: rate | K8: persons | L8: no. | M8: rate | O8: persons | P8: no. | Q8: rate | S8: persons | T8: no. | U8: rate | W8: persons | X8: no. | Y8: rate | AA8: persons | AB8: no. | AC8: rate | AE8: persons | AF8: no. | AG8: rate | AI8: persons | AJ8: no. | AK8: rate | AM8: persons | AN8: no. | AO8: rate | AQ8: persons | AR8: no. | AS8: rate
A9: 20110 | B9: Alpine | C9: 12068 | D9: 89 | E9: np | G9: 12183 | H9: 108 | I9: np | K9: 12283 | L9: 86 | M9: 1.8 | O9: 12355 | P9: 87 | Q9: 1.78 | S9: 12429 | T9: 99 | U9: 1.72 | W9: 12578 | X9: 97 | Y9: 1.77 | AA9: 12679 | AB9: 118 | AC9: 1.91 | AE9: 12807 | AF9: 93 | AG9: 1.79 | AI9: 12884 | AJ9: 95 | AK9: 1.71 | AM9: 13028 | AN9: 92 | AO9: 1.51 | AQ9: 13156 | AR9: 109 | AS9: 1.58
A10: 20260 | B10: Ararat | C10: 11326 | D10: 111 | E10: np | G10: 11400 | H10: 126 | I10: np | K10: 11490 | L10: 116 | M10: 2.24 | O10: 11560 | P10: 113 | Q10: 2.25 | S10: 11644 | T10: 108 | U10: 2.1 | W10: 11745 | X10: 112 | Y10: 2.06 | AA10: 11790 | AB10: 124 | AC10: 2.1 | AE10: 11792 | AF10: 101 | AG10: 2.03 | AI10: 11822 | AJ10: 125 | AK10: 2.03 | AM10: 11896 | AN10: 105 | AO10: 1.86 | AQ10: 11821 | AR10: 103 | AS10: 1.84
A11: 20570 | B11: Ballarat | C11: 95185 | D11: 1209 | E11: np | G11: 96728 | H11: 1323 | I11: np | K11: 98344 | L11: 1357 | M11: 1.99 | O11: 99914 | P11: 1258 | Q11: 1.98 | S11: 101479 | T11: 1288 | U11: 1.93 | W11: 103500 | X11: 1367 | Y11: 1.91 | AA11: 105498 | AB11: 1409 | AC11: 1.94 | AE11: 107518 | AF11: 1264 | AG11: 1.89 | AI11: 109650 | AJ11: 1297 | AK11: 1.81 | AM11: 111476 | AN11: 1225 | AO11: 1.69 | AQ11: 113482 | AR11: 1358 | AS11: 1.7
A12: 20660 | B12: Banyule | C12: 122983 | D12: 1726 | E12: np | G12: 123584 | H12: 1645 | I12: np | K12: 124314 | L12: 1635 | M12: 1.91 | O12: 125107 | P12: 1594 | Q12: 1.85 | S12: 126088 | T12: 1532 | U12: 1.79 | W12: 127447 | X12: 1757 | Y12: 1.83 | AA12: 128601 | AB12: 1628 | AC12: 1.82 | AE12: 129548 | AF12: 1572 | AG12: 1.82 | AI12: 130478 | AJ12: 1513 | AK12: 1.7 | AM12: 130121 | AN12: 1369 | AO12: 1.6 | AQ12: 127376 | AR12: 1413 | AS12: 1.55
A13: 20740 | B13: Bass Coast | C13: 30233 | D13: 365 | E13: np | G13: 30811 | H13: 344 | I13: np | K13: 31331 | L13: 302 | M13: 2.29 | O13: 31917 | P13: 362 | Q13: 2.26 | S13: 32576 | T13: 285 | U13: 2.11 | W13: 33464 | X13: 341 | Y13: 2.16 | AA13: 34726 | AB13: 367 | AC13: 2.1 | AE13: 36041 | AF13: 353 | AG13: 2.14 | AI13: 37382 | AJ13: 297 | AK13: 1.95 | AM13: 38869 | AN13: 295 | AO13: 1.73 | AQ13: 40641 | AR13: 370 | AS13: 1.7
A14: 20830 | B14: Baw Baw | C14: 43389 | D14: 515 | E14: np | G14: 44506 | H14: 529 | I14: np | K14: 45627 | L14: 524 | M14: 2.09 | O14: 46644 | P14: 552 | Q14: 2.09 | S14: 47837 | T14: 544 | U14: 2.05 | W14: 49296 | X14: 653 | Y14: 2.14 | AA14: 50852 | AB14: 625 | AC14: 2.14 | AE14: 52392 | AF14: 623 | AG14: 2.12 | AI14: 53970 | AJ14: 653 | AK14: 2.01 | AM14: 55647 | AN14: 619 | AO14: 1.91 | AQ14: 57580 | AR14: 726 | AS14: 1.92
A15: 20910 | B15: Bayside (Vic.) | C15: 96119 | D15: 948 | E15: np | G15: 96971 | H15: 927 | I15: np | K15: 98252 | L15: 935 | M15: 1.75 | O15: 99797 | P15: 979 | Q15: 1.77 | S15: 101268 | T15: 907 | U15: 1.73 | W15: 102912 | X15: 962 | Y15: 1.72 | AA15: 103621 | AB15: 956 | AC15: 1.69 | AE15: 104545 | AF15: 892 | AG15: 1.67 | AI15: 105029 | AJ15: 846 | AK15: 1.6 | AM15: 104881 | AN15: 791 | AO15: 1.51 | AQ15: 102337 | AR15: 851 | AS15: 1.54
A16: 21010 | B16: Benalla | C16: 13818 | D16: 105 | E16: np | G16: 13849 | H16: 143 | I16: np | K16: 13878 | L16: 134 | M16: 1.98 | O16: 13898 | P16: 140 | Q16: 2.13 | S16: 13923 | T16: 120 | U16: 1.99 | W16: 13982 | X16: 123 | Y16: 1.92 | AA16: 14041 | AB16: 136 | AC16: 1.88 | AE16: 14145 | AF16: 164 | AG16: 2.06 | AI16: 14219 | AJ16: 125 | AK16: 2.04 | AM16: 14358 | AN16: 129 | AO16: 1.98 | AQ16: 14431 | AR16: 136 | AS16: 1.86
A17: 21110 | B17: Boroondara | C17: 167062 | D17: 1561 | E17: np | G17: 168483 | H17: 1576 | I17: np | K17: 170485 | L17: 1511 | M17: 1.41 | O17: 172660 | P17: 1455 | Q17: 1.36 | S17: 174753 | T17: 1522 | U17: 1.32 | W17: 177276 | X17: 1635 | Y17: 1.34 | AA17: 178591 | AB17: 1520 | AC17: 1.34 | AE17: 179295 | AF17: 1392 | AG17: 1.29 | AI17: 179547 | AJ17: 1413 | AK17: 1.23 | AM17: 177722 | AN17: 1236 | AO17: 1.16 | AQ17: 169901 | AR17: 1228 | AS17: 1.15
A18: 21180 | B18: Brimbank | C18: 191496 | D18: 2812 | E18: np | G18: 193774 | H18: 3036 | I18: np | K18: 196169 | L18: 2822 | M18: 1.95 | O18: 198468 | P18: 2806 | Q18: 1.93 | S18: 200860 | T18: 2818 | U18: 1.87 | W18: 204190 | X18: 3065 | Y18: 1.9 | AA18: 206036 | AB18: 2964 | AC18: 1.91 | AE18: 206849 | AF18: 2812 | AG18: 1.9 | AI18: 206611 | AJ18: 2584 | AK18: 1.8 | AM18: 203999 | AN18: 2399 | AO18: 1.69 | AQ18: 196712 | AR18: 2180 | AS18: 1.6
A19: 21270 | B19: Buloke | C19: 6465 | D19: 42 | E19: np | G19: 6434 | H19: 52 | I19: np | K19: 6388 | L19: 55 | M19: 1.97 | O19: 6335 | P19: 52 | Q19: 2.14 | S19: 6306 | T19: 60 | U19: 2.24 | W19: 6284 | X19: 49 | Y19: 2.22 | AA19: 6218 | AB19: 51 | AC19: 2.2 | AE19: 6208 | AF19: 51 | AG19: 2.12 | AI19: 6159 | AJ19: 58 | AK19: 2.2 | AM19: 6146 | AN19: 64 | AO19: 2.35 | AQ19: 6130 | AR19: 62 | AS19: 2.43
A20: 21370 | B20: Campaspe | C20: 36855 | D20: 408 | E20: np | G20: 37041 | H20: 431 | I20: np | K20: 37213 | L20: 447 | M20: 2.3 | O20: 37338 | P20: 428 | Q20: 2.32 | S20: 37429 | T20: 408 | U20: 2.26 | W20: 37595 | X20: 430 | Y20: 2.21 | AA20: 37780 | AB20: 397 | AC20: 2.14 | AE20: 37913 | AF20: 395 | AG20: 2.08 | AI20: 38084 | AJ20: 391 | AK20: 1.97 | AM20: 38317 | AN20: 384 | AO20: 1.92 | AQ20: 38545 | AR20: 396 | AS20: 1.93
... A68: 25990 | B68: Pyrenees | C68: 6759 | D68: 72 | E68: np | G68: 6860 | H68: 58 | I68: np | K68: 6938 | L68: 60 | M68: 2.26 | O68: 7047 | P68: 69 | Q68: 2.22 | S68: 7179 | T68: 58 | U68: 2.19 | W68: 7316 | X68: 58 | Y68: 2.1 | AA68: 7320 | AB68: 56 | AC68: 1.93 | AE68: 7320 | AF68: 57 | AG68: 1.88 | AI68: 7438 | AJ68: 59 | AK68: 1.85 | AM68: 7530 | AN68: 68 | AO68: 1.94 | AQ68: 7613 | AR68: 54 | AS68: 1.89
A69: 26080 | B69: Queenscliffe | C69: 3061 | D69: 18 | E69: np | G69: 3057 | H69: 21 | I69: np | K69: 3002 | L69: 13 | M69: 1.55 | O69: 2970 | P69: 16 | Q69: 1.67 | S69: 2933 | T69: 6 | U69: np | W69: 2929 | X69: 16 | Y69: 1.43 | AA69: 2921 | AB69: 17 | AC69: 1.47 | AE69: 2951 | AF69: 18 | AG69: 1.9 | AI69: 2968 | AJ69: 16 | AK69: 1.93 | AM69: 3089 | AN69: 12 | AO69: 1.76 | AQ69: 3235 | AR69: 21 | AS69: np
A70: 26170 | B70: South Gippsland | C70: 27512 | D70: 286 | E70: np | G70: 27926 | H70: 306 | I70: np | K70: 28273 | L70: 311 | M70: 2.26 | O70: 28521 | P70: 309 | Q70: 2.31 | S70: 28781 | T70: 286 | U70: 2.26 | W70: 29122 | X70: 310 | Y70: 2.23 | AA70: 29346 | AB70: 282 | AC70: 2.13 | AE70: 29577 | AF70: 289 | AG70: 2.08 | AI70: 29887 | AJ70: 267 | AK70: 1.92 | AM70: 30222 | AN70: 247 | AO70: 1.82 | AQ70: 30378 | AR70: 257 | AS70: 1.8
A71: 26260 | B71: Southern Grampians | C71: 16571 | D71: 169 | E71: np | G71: 16461 | H71: 186 | I71: np | K71: 16355 | L71: 181 | M71: 2.19 | O71: 16255 | P71: 159 | Q71: 2.16 | S71: 16162 | T71: 168 | U71: 2.11 | W71: 16123 | X71: 197 | Y71: 2.19 | AA71: 16199 | AB71: 193 | AC71: 2.32 | AE71: 16276 | AF71: 177 | AG71: 2.34 | AI71: 16360 | AJ71: 164 | AK71: 2.16 | AM71: 16479 | AN71: 169 | AO71: 2.03 | AQ71: 16488 | AR71: 178 | AS71: 2.04
A72: 26350 | B72: Stonnington | C72: 98853 | D72: 979 | E72: np | G72: 101410 | H72: 1085 | I72: np | K72: 103487 | L72: 1049 | M72: 1.16 | O72: 105894 | P72: 1047 | Q72: 1.15 | S72: 108028 | T72: 1017 | U72: 1.1 | W72: 111003 | X72: 1135 | Y72: 1.09 | AA72: 112102 | AB72: 1187 | AC72: 1.11 | AE72: 113287 | AF72: 1035 | AG72: 1.1 | AI72: 113739 | AJ72: 1033 | AK72: 1.06 | AM72: 112524 | AN72: 898 | AO72: 0.97 | AQ72: 106278 | AR72: 998 | AS72: 0.97
A73: 26430 | B73: Strathbogie | C73: 9598 | D73: 80 | E73: np | G73: 9744 | H73: 87 | I73: np | K73: 9867 | L73: 86 | M73: 2.08 | O73: 10018 | P73: 78 | Q73: 2.02 | S73: 10175 | T73: 91 | U73: 1.98 | W73: 10357 | X73: 88 | Y73: 1.94 | AA73: 10527 | AB73: 93 | AC73: 1.99 | AE73: 10724 | AF73: 95 | AG73: 1.98 | AI73: 10894 | AJ73: 92 | AK73: 1.95 | AM73: 11139 | AN73: 82 | AO73: 1.82 | AQ73: 11364 | AR73: 115 | AS73: 1.97
A74: 26490 | B74: Surf Coast | C74: 26666 | D74: 321 | E74: np | G74: 27530 | H74: 359 | I74: np | K74: 28228 | L74: 322 | M74: 2.01 | O74: 28874 | P74: 299 | Q74: 1.9 | S74: 29625 | T74: 326 | U74: 1.81 | W74: 30465 | X74: 360 | Y74: 1.84 | AA74: 31535 | AB74: 344 | AC74: 1.86 | AE74: 32715 | AF74: 391 | AG74: 1.9 | AI74: 34164 | AJ74: 372 | AK74: 1.82 | AM74: 35758 | AN74: 360 | AO74: 1.76 | AQ74: 37623 | AR74: 450 | AS74: 1.79
A75: 26610 | B75: Swan Hill | C75: 20865 | D75: 297 | E75: np | G75: 20971 | H75: 346 | I75: np | K75: 21003 | L75: 318 | M75: 2.6 | O75: 20940 | P75: 254 | Q75: 2.47 | S75: 20893 | T75: 293 | U75: 2.32 | W75: 20896 | X75: 326 | Y75: 2.34 | AA75: 21059 | AB75: 324 | AC75: 2.48 | AE75: 21224 | AF75: 307 | AG75: 2.44 | AI75: 21387 | AJ75: 273 | AK75: 2.2 | AM75: 21472 | AN75: 304 | AO75: 2.08 | AQ75: 21383 | AR75: 288 | AS75: 1.99
A76: 26670 | B76: Towong | C76: 5918 | D76: 52 | E76: np | G76: 5940 | H76: 47 | I76: np | K76: 5961 | L76: 44 | M76: 2.04 | O76: 5982 | P76: 54 | Q76: 2 | S76: 6005 | T76: 53 | U76: 2.08 | W76: 6046 | X76: 67 | Y76: 2.38 | AA76: 6060 | AB76: 60 | AC76: 2.45 | AE76: 6094 | AF76: 42 | AG76: 2.29 | AI76: 6134 | AJ76: 42 | AK76: 1.94 | AM76: 6160 | AN76: 44 | AO76: 1.71 | AQ76: 6183 | AR76: 55 | AS76: 1.87
A77: 26700 | B77: Wangaratta | C77: 27212 | D77: 314 | E77: np | G77: 27438 | H77: 322 | I77: np | K77: 27650 | L77: 282 | M77: 2.18 | O77: 27862 | P77: 267 | Q77: 2.05 | S77: 28143 | T77: 300 | U77: 1.97 | W77: 28592 | X77: 299 | Y77: 1.98 | AA77: 28936 | AB77: 333 | AC77: 2.09 | AE77: 29241 | AF77: 292 | AG77: 2.03 | AI77: 29403 | AJ77: 293 | AK77: 1.97 | AM77: 29468 | AN77: 285 | AO77: 1.83 | AQ77: 29740 | AR77: 300 | AS77: 1.85
A78: 26730 | B78: Warrnambool | C78: 32667 | D78: 396 | E78: np | G78: 33059 | H78: 416 | I78: np | K78: 33423 | L78: 363 | M78: 1.9 | O78: 33729 | P78: 398 | Q78: 1.89 | S78: 34005 | T78: 359 | U78: 1.78 | W78: 34242 | X78: 440 | Y78: 1.89 | AA78: 34501 | AB78: 346 | AC78: 1.78 | AE78: 34791 | AF78: 399 | AG78: 1.81 | AI78: 35060 | AJ78: 359 | AK78: 1.66 | AM78: 35358 | AN78: 366 | AO78: 1.68 | AQ78: 35419 | AR78: 357 | AS78: 1.61
A79: 26810 | B79: Wellington | C79: 42068 | D79: 458 | E79: np | G79: 42445 | H79: 519 | I79: np | K79: 42721 | L79: 461 | M79: 2.12 | O79: 42948 | P79: 438 | Q79: 2.08 | S79: 43172 | T79: 474 | U79: 1.99 | W79: 43530 | X79: 510 | Y79: 2.04 | AA79: 43849 | AB79: 511 | AC79: 2.12 | AE79: 44191 | AF79: 475 | AG79: 2.1 | AI79: 44620 | AJ79: 479 | AK79: 2.03 | AM79: 45029 | AN79: 440 | AO79: 1.91 | AQ79: 45452 | AR79: 459 | AS79: 1.89
A80: 26890 | B80: West Wimmera | C80: 4287 | D80: 40 | E80: np | G80: 4214 | H80: 40 | I80: np | K80: 4124 | L80: 43 | M80: 2.24 | O80: 4038 | P80: 39 | Q80: 2.21 | S80: 3974 | T80: 42 | U80: 2.24 | W80: 3937 | X80: 40 | Y80: 2.21 | AA80: 3951 | AB80: 46 | AC80: 2.38 | AE80: 3962 | AF80: 53 | AG80: 2.59 | AI80: 3974 | AJ80: 40 | AK80: 2.62 | AM80: 3988 | AN80: 55 | AO80: 2.82 | AQ80: 3977 | AR80: 42 | AS80: 2.65
A81: 26980 | B81: Whitehorse | C81: 157538 | D81: 1874 | E81: np | G81: 159661 | H81: 1915 | I81: np | K81: 162081 | L81: 1752 | M81: 1.69 | O81: 164320 | P81: 1891 | Q81: 1.67 | S81: 166679 | T81: 1735 | U81: 1.58 | W81: 169641 | X81: 1845 | Y81: 1.57 | AA81: 172315 | AB81: 1858 | AC81: 1.52 | AE81: 174332 | AF81: 1647 | AG81: 1.46 | AI81: 175738 | AJ81: 1600 | AK81: 1.37 | AM81: 176622 | AN81: 1471 | AO81: 1.26 | AQ81: 171167 | AR81: 1381 | AS81: 1.19
... A87: 27630 | B87: Yarriambiack | C87: 7183 | D87: 73 | E87: np | G87: 7095 | H87: 57 | I87: np | K87: 7032 | L87: 60 | M87: 2.45 | O87: 6924 | P87: 50 | Q87: 2.09 | S87: 6826 | T87: 59 | U87: 2.09 | W87: 6743 | X87: 63 | Y87: 2.07 | AA87: 6705 | AB87: 64 | AC87: 2.21 | AE87: 6693 | AF87: 63 | AG87: 2.25 | AI87: 6669 | AJ87: 47 | AK87: 2.06 | AM87: 6633 | AN87: 69 | AO87: 2.1 | AQ87: 6511 | AR87: 57 | AS87: 2.06
A88: 29399 | B88: Unincorporated Vic | C88: 769 | D88: 3 | E88: np | G88: 797 | H88: 5 | I88: np | K88: 808 | L88: 0 | M88: np | O88: 835 | P88: 3 | Q88: np | S88: 862 | T88: 3 | U88: np | W88: 892 | X88: 5 | Y88: np | AA88: 901 | AB88: 4 | AC88: np | AE88: 911 | AF88: 3 | AG88: np | AI88: 918 | AJ88: 6 | AK88: np | AM88: 932 | AN88: 0 | AO88: np | AQ88: 946 | AR88: 3 | AS88: np
A89: 2 | B89: Total Victoria | C89: 5537817 | D89: 71444 | E89: np | G89: 5651091 | H89: 77405 | I89: np | K89: 5772669 | L89: 73969 | M89: 1.81 | O89: 5894917 | P89: 74224 | Q89: 1.79 | S89: 6022322 | T89: 73568 | U89: 1.71 | W89: 6173172 | X89: 82892 | Y89: 1.73 | AA89: 6299798 | AB89: 82094 | AC89: 1.74 | AE89: 6418168 | AF89: 78488 | AG89: 1.72 | AI89: 6530852 | AJ89: 77220 | AK89: 1.64 | AM89: 6606149 | AN89: 73543 | AO89: 1.55 | AQ89: 6548040 | AR89: 75363 | AS89: 1.52
A91: 0 nil or rounded to zero (including null cells)
A92: np not available for publication but included in totals where applicable, unless otherwise indicated
A95: © Commonwealth of Australia 2022

Sheet death_vic
A1: Australian Bureau of Statistics
A2: 33020DO005_2022 Deaths, Australia, 2022
A3: Released at 11:30 am (Canberra time) Thurs 28 Sep 2023
A4: Table 5.2 Deaths, Summary, Local Government Area, Victoria–2012 to 2022
C5: 2012 | G5: 2013 | K5: 2014 | O5: 2015 | S5: 2016 | W5: 2017 | AA5: 2018 | AE5: 2019 | AI5: 2020 | AM5: 2021 | AQ5: 2022
C6: Estimated resident population | D6: Deaths | E6: Standardised death rate | G6: Estimated resident population | H6: Deaths | I6: Standardised death rate | K6: Estimated resident population | L6: Deaths | M6: Standardised death rate | O6: Estimated resident population | P6: Deaths | Q6: Standardised death rate | S6: Estimated resident population | T6: Deaths | U6: Standardised death rate | W6: Estimated resident population | X6: Deaths | Y6: Standardised death rate | AA6: Estimated resident population | AB6: Deaths | AC6: Standardised death rate | AE6: Estimated resident population | AF6: Deaths | AG6: Standardised death rate | AI6: Estimated resident population | AJ6: Deaths | AK6: Standardised death rate | AM6: Estimated resident population | AN6: Deaths | AO6: Standardised death rate | AQ6: Estimated resident population | AR6: Deaths | AS6: Standardised death rate
A7: LGA Code 2023 | B7: 2023 LGA Name | C7: persons | D7: no. | E7: rate | G7: persons | H7: no. | I7: rate | K7: persons | L7: no. | M7: rate | O7: persons | P7: no. | Q7: rate | S7: persons | T7: no. | U7: rate | W7: persons | X7: no. | Y7: rate | AA7: persons | AB7: no. | AC7: rate | AE7: persons | AF7: no. | AG7: rate | AI7: persons | AJ7: no. | AK7: rate | AM7: persons | AN7: no. | AO7: rate | AQ7: persons | AR7: no. | AS7: rate
A8: 20110 | B8: Alpine | C8: 12183 | D8: 109 | E8: np | G8: 12283 | H8: 126 | I8: 5.5 | K8: 12355 | L8: 109 | M8: 5.6 | O8: 12429 | P8: 120 | Q8: 5.6 | S8: 12578 | T8: 128 | U8: 5.6 | W8: 12687 | X8: 139 | Y8: 5.7 | AA8: 12822 | AB8: 131 | AC8: 5.8 | AE8: 12904 | AF8: 152 | AG8: 6.1 | AI8: 13054 | AJ8: 104 | AK8: 5.6 | AM8: 13166 | AN8: 134 | AO8: 5.6 | AQ8: 13187 | AR8: 122 | AS8: 5.1
A9: 20260 | B9: Ararat | C9: 11400 | D9: 117 | E9: np | G9: 11490 | H9: 124 | I9: 6.8 | K9: 11560 | L9: 119 | M9: 6.2 | O9: 11644 | P9: 107 | Q9: 5.9 | S9: 11745 | T9: 119 | U9: 5.8 | W9: 11796 | X9: 134 | Y9: 5.9 | AA9: 11805 | AB9: 108 | AC9: 6 | AE9: 11838 | AF9: 128 | AG9: 6.2 | AI9: 11918 | AJ9: 104 | AK9: 5.6 | AM9: 11827 | AN9: 128 | AO9: 5.8 | AQ9: 11754 | AR9: 128 | AS9: 5.7
A10: 20570 | B10: Ballarat | C10: 96728 | D10: 699 | E10: np | G10: 98344 | H10: 751 | I10: 6.2 | K10: 99914 | L10: 797 | M10: 6 | O10: 101479 | P10: 833 | Q10: 6.2 | S10: 103500 | T10: 808 | U10: 6.2 | W10: 105551 | X10: 827 | Y10: 6.1 | AA10: 107608 | AB10: 821 | AC10: 5.9 | AE10: 109773 | AF10: 947 | AG10: 6 | AI10: 111645 | AJ10: 835 | AK10: 5.9 | AM10: 113504 | AN10: 928 | AO10: 5.9 | AQ10: 115951 | AR10: 1085 | AS10: 5.9
A11: 20660 | B11: Banyule | C11: 123584 | D11: 841 | E11: np | G11: 124314 | H11: 826 | I11: 5.1 | K11: 125107 | L11: 852 | M11: 4.8 | O11: 126088 | P11: 885 | Q11: 4.8 | S11: 127447 | T11: 799 | U11: 4.8 | W11: 128660 | X11: 885 | Y11: 4.7 | AA11: 129645 | AB11: 855 | AC11: 4.6 | AE11: 130607 | AF11: 1002 | AG11: 4.9 | AI11: 130294 | AJ11: 884 | AK11: 4.8 | AM11: 127370 | AN11: 878 | AO11: 4.8 | AQ11: 127348 | AR11: 1057 | AS11: 4.9
A12: 20740 | B12: Bass Coast | C12: 30811 | D12: 313 | E12: np | G12: 31331 | H12: 317 | I12: 5.7 | K12: 31917 | L12: 314 | M12: 5.5 | O12: 32576 | P12: 355 | Q12: 5.6 | S12: 33464 | T12: 325 | U12: 5.5 | W12: 34748 | X12: 384 | Y12: 5.6 | AA12: 36083 | AB12: 367 | AC12: 5.5 | AE12: 37440 | AF12: 375 | AG12: 5.5 | AI12: 38950 | AJ12: 376 | AK12: 5.3 | AM12: 40675 | AN12: 401 | AO12: 5.2 | AQ12: 41798 | AR12: 444 | AS12: 5.2
A13: 20830 | B13: Baw Baw | C13: 44506 | D13: 301 | E13: np | G13: 45627 | H13: 295 | I13: 5.2 | K13: 46644 | L13: 326 | M13: 5.2 | O13: 47837 | P13: 368 | Q13: 5.4 | S13: 49296 | T13: 376 | U13: 5.5 | W13: 50883 | X13: 369 | Y13: 5.4 | AA13: 52447 | AB13: 390 | AC13: 5.2 | AE13: 54047 | AF13: 414 | AG13: 5.2 | AI13: 55753 | AJ13: 437 | AK13: 5.3 | AM13: 57618 | AN13: 453 | AO13: 5.3 | AQ13: 59248 | AR13: 482 | AS13: 5.3
A14: 20910 | B14: Bayside (Vic.) | C14: 96971 | D14: 828 | E14: np | G14: 98252 | H14: 764 | I14: 4.7 | K14: 99797 | L14: 761 | M14: 4.6 | O14: 101268 | P14: 828 | Q14: 4.5 | S14: 102912 | T14: 801 | U14: 4.4 | W14: 103665 | X14: 794 | Y14: 4.4 | AA14: 104623 | AB14: 724 | AC14: 4.2 | AE14: 105128 | AF14: 849 | AG14: 4.3 | AI14: 105018 | AJ14: 817 | AK14: 4.3 | AM14: 102328 | AN14: 798 | AO14: 4.3 | AQ14: 102177 | AR14: 875 | AS14: 4.3
A15: 21010 | B15: Benalla | C15: 13849 | D15: 157 | E15: np | G15: 13878 | H15: 138 | I15: 6.2 | K15: 13898 | L15: 148 | M15: 5.9 | O15: 13923 | P15: 168 | Q15: 6.1 | S15: 13982 | T15: 160 | U15: 6.1 | W15: 14049 | X15: 181 | Y15: 6.4 | AA15: 14158 | AB15: 149 | AC15: 6 | AE15: 14237 | AF15: 168 | AG15: 6.1 | AI15: 14382 | AJ15: 171 | AK15: 5.8 | AM15: 14436 | AN15: 175 | AO15: 5.8 | AQ15: 14457 | AR15: 220 | AS15: 6.2
A16: 21110 | B16: Boroondara | C16: 168483 | D16: 1084 | E16: np | G16: 170485 | H16: 1138 | I16: 4.5 | K16: 172660 | L16: 1122 | M16: 4.4 | O16: 174753 | P16: 1138 | Q16: 4.5 | S16: 177276 | T16: 1146 | U16: 4.4 | W16: 178650 | X16: 1128 | Y16: 4.3 | AA16: 179386 | AB16: 1049 | AC16: 4.2 | AE16: 179663 | AF16: 1156 | AG16: 4.1 | AI16: 177875 | AJ16: 999 | AK16: 3.9 | AM16: 169789 | AN16: 1055 | AO16: 3.9 | AQ16: 169500 | AR16: 1248 | AS16: 4
A17: 21180 | B17: Brimbank | C17: 193774 | D17: 950 | E17: np | G17: 196169 | H17: 953 | I17: 5.5 | K17: 198468 | L17: 1026 | M17: 5.4 | O17: 200860 | P17: 1097 | Q17: 5.4 | S17: 204190 | T17: 1122 | U17: 5.5 | W17: 206116 | X17: 1136 | Y17: 5.5 | AA17: 206977 | AB17: 1104 | AC17: 5.3 | AE17: 206771 | AF17: 1287 | AG17: 5.4 | AI17: 204213 | AJ17: 1202 | AK17: 5.3 | AM17: 196631 | AN17: 1164 | AO17: 5.3 | AQ17: 193256 | AR17: 1365 | AS17: 5.2
A18: 21270 | B18: Buloke | C18: 6434 | D18: 89 | E18: np | G18: 6388 | H18: 60 | I18: 5.9 | K18: 6335 | L18: 79 | M18: 5.9 | O18: 6306 | P18: 91 | Q18: 5.7 | S18: 6284 | T18: 109 | U18: 6.6 | W18: 6221 | X18: 91 | Y18: 6.8 | AA18: 6214 | AB18: 81 | AC18: 6.5 | AE18: 6166 | AF18: 76 | AG18: 5.9 | AI18: 6156 | AJ18: 81 | AK18: 5.6 | AM18: 6132 | AN18: 83 | AO18: 5.9 | AQ18: 6118 | AR18: 88 | AS18: 6.2
A19: 21370 | B19: Campaspe | C19: 37041 | D19: 310 | E19: np | G19: 37213 | H19: 319 | I19: 5.9 | K19: 37338 | L19: 373 | M19: 5.7 | O19: 37429 | P19: 376 | Q19: 6 | S19: 37595 | T19: 350 | U19: 6 | W19: 37799 | X19: 414 | Y19: 5.9 | AA19: 37948 | AB19: 418 | AC19: 5.9 | AE19: 38128 | AF19: 396 | AG19: 6 | AI19: 38379 | AJ19: 427 | AK19: 6 | AM19: 38556 | AN19: 360 | AO19: 5.6 | AQ19: 38541 | AR19: 492 | AS19: 6
... A67: 25990 | B67: Pyrenees | C67: 6860 | D67: 56 | E67: np | G67: 6938 | H67: 52 | I67: 5.6 | K67: 7047 | L67: 68 | M67: 5.8 | O67: 7179 | P67: 69 | Q67: 6 | S67: 7316 | T67: 82 | U67: 6.6 | W67: 7325 | X67: 57 | Y67: 6.1 | AA67: 7327 | AB67: 66 | AC67: 5.8 | AE67: 7449 | AF67: 72 | AG67: 5.3 | AI67: 7544 | AJ67: 73 | AK67: 5.4 | AM67: 7619 | AN67: 72 | AO67: 5.5 | AQ67: 7651 | AR67: 73 | AS67: 5.4
A68: 26080 | B68: Queenscliffe | C68: 3057 | D68: 34 | E68: np | G68: 3002 | H68: 33 | I68: np | K68: 2970 | L68: 43 | M68: np | O68: 2933 | P68: 28 | Q68: np | S68: 2929 | T68: 31 | U68: np | W68: 2923 | X68: 27 | Y68: np | AA68: 2954 | AB68: 39 | AC68: np | AE68: 2973 | AF68: 33 | AG68: np | AI68: 3095 | AJ68: 34 | AK68: np | AM68: 3236 | AN68: 32 | AO68: np | AQ68: 3220 | AR68: 33 | AS68: np
A69: 26170 | B69: South Gippsland | C69: 27926 | D69: 218 | E69: np | G69: 28273 | H69: 222 | I69: 5.1 | K69: 28521 | L69: 254 | M69: 5.2 | O69: 28781 | P69: 246 | Q69: 5.3 | S69: 29122 | T69: 255 | U69: 5.5 | W69: 29361 | X69: 252 | Y69: 5.2 | AA69: 29604 | AB69: 257 | AC69: 5.2 | AE69: 29923 | AF69: 300 | AG69: 5.4 | AI69: 30272 | AJ69: 308 | AK69: 5.7 | AM69: 30388 | AN69: 277 | AO69: 5.6 | AQ69: 30697 | AR69: 336 | AS69: 5.5
A70: 26260 | B70: Southern Grampians | C70: 16461 | D70: 194 | E70: np | G70: 16355 | H70: 196 | I70: 6.7 | K70: 16255 | L70: 164 | M70: 6.4 | O70: 16162 | P70: 211 | Q70: 6.3 | S70: 16123 | T70: 168 | U70: 6.1 | W70: 16207 | X70: 165 | Y70: 6.1 | AA70: 16291 | AB70: 160 | AC70: 5.4 | AE70: 16378 | AF70: 202 | AG70: 5.7 | AI70: 16506 | AJ70: 160 | AK70: 5.6 | AM70: 16492 | AN70: 209 | AO70: 6 | AQ70: 16393 | AR70: 203 | AS70: 6
A71: 26350 | B71: Stonnington | C71: 101410 | D71: 541 | E71: np | G71: 103487 | H71: 609 | I71: 4.4 | K71: 105894 | L71: 604 | M71: 4.4 | O71: 108028 | P71: 600 | Q71: 4.5 | S71: 111003 | T71: 633 | U71: 4.4 | W71: 112134 | X71: 647 | Y71: 4.4 | AA71: 113340 | AB71: 575 | AC71: 4.3 | AE71: 113800 | AF71: 723 | AG71: 4.4 | AI71: 112610 | AJ71: 614 | AK71: 4.2 | AM71: 106190 | AN71: 651 | AO71: 4.4 | AQ71: 106418 | AR71: 750 | AS71: 4.4
A72: 26430 | B72: Strathbogie | C72: 9744 | D72: 125 | E72: np | G72: 9867 | H72: 111 | I72: 6.2 | K72: 10018 | L72: 110 | M72: 5.9 | O72: 10175 | P72: 138 | Q72: 6 | S72: 10357 | T72: 108 | U72: 5.8 | W72: 10532 | X72: 120 | Y72: 5.7 | AA72: 10734 | AB72: 125 | AC72: 5.5 | AE72: 10907 | AF72: 116 | AG72: 5.2 | AI72: 11158 | AJ72: 118 | AK72: 5.1 | AM72: 11368 | AN72: 137 | AO72: 5.2 | AQ72: 11510 | AR72: 139 | AS72: 5.4
A73: 26490 | B73: Surf Coast | C73: 27530 | D73: 160 | E73: np | G73: 28228 | H73: 167 | I73: 4.9 | K73: 28874 | L73: 155 | M73: 4.8 | O73: 29625 | P73: 191 | Q73: 5 | S73: 30465 | T73: 185 | U73: 5 | W73: 31555 | X73: 151 | Y73: 4.7 | AA73: 32750 | AB73: 197 | AC73: 4.6 | AE73: 34213 | AF73: 213 | AG73: 4.6 | AI73: 35827 | AJ73: 202 | AK73: 4.8 | AM73: 37648 | AN73: 199 | AO73: 4.4 | AQ73: 38652 | AR73: 253 | AS73: 4.4
A74: 26610 | B74: Swan Hill | C74: 20971 | D74: 161 | E74: np | G74: 21003 | H74: 160 | I74: 5.9 | K74: 20940 | L74: 164 | M74: 5.6 | O74: 20893 | P74: 183 | Q74: 5.8 | S74: 20896 | T74: 192 | U74: 6.1 | W74: 21069 | X74: 196 | Y74: 6.4 | AA74: 21240 | AB74: 180 | AC74: 6.2 | AE74: 21407 | AF74: 195 | AG74: 6.2 | AI74: 21499 | AJ74: 157 | AK74: 5.8 | AM74: 21381 | AN74: 192 | AO74: 5.8 | AQ74: 21225 | AR74: 224 | AS74: 6
A75: 26670 | B75: Towong | C75: 5940 | D75: 55 | E75: np | G75: 5961 | H75: 69 | I75: 6.2 | K75: 5982 | L75: 64 | M75: 5.9 | O75: 6005 | P75: 64 | Q75: 5.9 | S75: 6046 | T75: 74 | U75: 5.8 | W75: 6064 | X75: 48 | Y75: 5.2 | AA75: 6100 | AB75: 64 | AC75: 5.3 | AE75: 6142 | AF75: 79 | AG75: 5.5 | AI75: 6170 | AJ75: 56 | AK75: 5.8 | AM75: 6186 | AN75: 67 | AO75: 5.8 | AQ75: 6196 | AR75: 57 | AS75: 5
A76: 26700 | B76: Wangaratta | C76: 27438 | D76: 242 | E76: np | G76: 27650 | H76: 268 | I76: 5.8 | K76: 27862 | L76: 276 | M76: 5.7 | O76: 28143 | P76: 265 | Q76: 5.8 | S76: 28592 | T76: 280 | U76: 5.8 | W76: 28951 | X76: 267 | Y76: 5.6 | AA76: 29269 | AB76: 292 | AC76: 5.6 | AE76: 29439 | AF76: 285 | AG76: 5.5 | AI76: 29517 | AJ76: 271 | AK76: 5.5 | AM76: 29751 | AN76: 260 | AO76: 5.2 | AQ76: 29903 | AR76: 329 | AS76: 5.3
A77: 26730 | B77: Warrnambool | C77: 33059 | D77: 240 | E77: np | G77: 33423 | H77: 290 | I77: 5.7 | K77: 33729 | L77: 288 | M77: 5.9 | O77: 34005 | P77: 283 | Q77: 6 | S77: 34242 | T77: 293 | U77: 5.9 | W77: 34520 | X77: 301 | Y77: 5.8 | AA77: 34823 | AB77: 278 | AC77: 5.6 | AE77: 35104 | AF77: 316 | AG77: 5.7 | AI77: 35418 | AJ77: 289 | AK77: 5.5 | AM77: 35433 | AN77: 316 | AO77: 5.6 | AQ77: 35559 | AR77: 372 | AS77: 5.7
A78: 26810 | B78: Wellington | C78: 42445 | D78: 377 | E78: np | G78: 42721 | H78: 368 | I78: 6.6 | K78: 42948 | L78: 364 | M78: 6.3 | O78: 43172 | P78: 424 | Q78: 6.4 | S78: 43530 | T78: 384 | U78: 6.4 | W78: 43872 | X78: 425 | Y78: 6.6 | AA78: 44233 | AB78: 383 | AC78: 6.3 | AE78: 44676 | AF78: 415 | AG78: 6.3 | AI78: 45105 | AJ78: 404 | AK78: 6.1 | AM78: 45469 | AN78: 432 | AO78: 6.1 | AQ78: 45799 | AR78: 487 | AS78: 6.3
A79: 26890 | B79: West Wimmera | C79: 4214 | D79: 35 | E79: np | G79: 4124 | H79: 43 | I79: 6.3 | K79: 4038 | L79: 48 | M79: 6.2 | O79: 3974 | P79: 58 | Q79: 7.4 | S79: 3937 | T79: 47 | U79: 7.7 | W79: 3952 | X79: 40 | Y79: 7.4 | AA79: 3964 | AB79: 46 | AC79: 6.3 | AE79: 3979 | AF79: 37 | AG79: 5.5 | AI79: 3994 | AJ79: 41 | AK79: 5.2 | AM79: 3978 | AN79: 36 | AO79: 4.8 | AQ79: 3942 | AR79: 51 | AS79: 5.5
A80: 26980 | B80: Whitehorse | C80: 159661 | D80: 1156 | E80: np | G80: 162081 | H80: 1116 | I80: 4.7 | K80: 164320 | L80: 1179 | M80: 4.7 | O80: 166679 | P80: 1119 | Q80: 4.6 | S80: 169641 | T80: 1171 | U80: 4.5 | W80: 172376 | X80: 1066 | Y80: 4.3 | AA80: 174431 | AB80: 1007 | AC80: 4.1 | AE80: 175862 | AF80: 1247 | AG80: 4.1 | AI80: 176794 | AJ80: 1108 | AK80: 4.1 | AM80: 171077 | AN80: 1202 | AO80: 4.3 | AQ80: 172466 | AR80: 1300 | AS80: 4.2
... A86: 27630 | B86: Yarriambiack | C86: 7095 | D86: 89 | E86: np | G86: 7032 | H86: 89 | I86: 6.2 | K86: 6924 | L86: 90 | M86: 5.9 | O86: 6826 | P86: 82 | Q86: 5.6 | S86: 6743 | T86: 92 | U86: 5.7 | W86: 6708 | X86: 89 | Y86: 5.6 | AA86: 6698 | AB86: 116 | AC86: 6.4 | AE86: 6675 | AF86: 110 | AG86: 6.9 | AI86: 6641 | AJ86: 86 | AK86: 7 | AM86: 6510 | AN86: 83 | AO86: 6.6 | AQ86: 6435 | AR86: 112 | AS86: 6.7
A87: 29399 | B87: Unincorporated Vic | C87: 797 | D87: 3 | E87: np | G87: 808 | H87: 0 | I87: np | K87: 835 | L87: 0 | M87: np | O87: 862 | P87: 0 | Q87: np | S87: 892 | T87: 0 | U87: np | W87: 901 | X87: 5 | Y87: np | AA87: 911 | AB87: 0 | AC87: np | AE87: 918 | AF87: 0 | AG87: np | AI87: 934 | AJ87: 0 | AK87: np | AM87: 946 | AN87: 0 | AO87: np | AQ87: 961 | AR87: 0 | AS87: np
B88: Total Victoria | C88: 5651091 | D88: 35760 | E88: np | G88: 5772669 | H88: 35916 | I88: 5.4 | K88: 5894917 | L88: 38042 | M88: 5.3 | O88: 6022322 | P88: 39904 | Q88: 5.3 | S88: 6173172 | T88: 39450 | U88: 5.3 | W88: 6302608 | X88: 39791 | Y88: 5.3 | AA88: 6423038 | AB88: 38231 | AC88: 5 | AE88: 6537305 | AF88: 43944 | AG88: 5.1 | AI88: 6615046 | AJ88: 41093 | AK88: 5 | AM88: 6547822 | AN88: 42486 | AO88: 5.1 | AQ88: 6625964 | AR88: 47978 | AS88: 5.1
A90: 0 nil or rounded to zero (including null cells)
A91: np not available for publication but included in totals where applicable, unless otherwise indicated
A94: © Commonwealth of Australia 2023

Sheet key dates
B1: Real Life | F1: Code Analysis | H1: Vaccine Period
B3: 43916 | C3: 第一次死人
B5: 43921 | D5: lockdown1 (43 days)
B6: 43963
B8: 44021 | D8: lockdown2 (111 days) | F8: 44021
F11: =F8+28 -> 44049 | G11: 4 week
F12: =F8+56 -> 44077 | G12: 8 week
B14: 44131
B18: 44250 | C18: 疫苗开始 | H18: 44250
B20: 44240 | C20: UK | D20: lockdown3 (5 days)
B21: 44244
B23: 44344 | C23: delta
B25: 44344 | D25: lockdown4 (14 days)
B26: 44357
B28: 44393 | D28: lockdown5 (12 days)
B29: 44404
B31: 44413 | D31: lockdown6 (77 days)
B32: 44429 | C32: 封州
H33: 44437 | I33: 44437
B34: 44456 | C34: 第一针70%，解封 | F34: 44456
B36: 44468 | C36: 补贴降低，解封
B38: 44471 | C38: 第一针80%
I39: 44473
B40: 44477 | C40: delta plus
B41: 44480 | C41: 加强针开始
H42: 44480 | I42: 44480
F43: =F34+28 -> 44484 | G43: 4 week
B46: 44490
B50: 44498 | C50: 疫苗两针80%，解封
B52: 44501 | C52: 边境开放 | D52: test kit $15 超市售卖 | F52: =F43+28 -> 44512 | G52: 8 week | I52: 44501
B54: 44519 | C54: 解封第一天
B56: 44537 | C56: omicron | F56: 44537
B58: 44545 | C58: vaccine data miss
F60: =F56+28 -> 44565 | G60: 4 week
B61: 44574 | C61: recovers data miss
B63: 44579 | C63: 补贴降低 | D63: not report 导致数据不准
B65: 44585 | C65: free RAT test kit | D65: 测试数据变多
F66: 44593 | G66: 8 week
B67: 44606 | C67: 加强针50% | H67: 44606

Sheet regression sens->

Sheet reg control
K1: top | L1: bottom
C2: top | K2: k0 = 0.0067 | L2: k0 = 0.0053 | N2: k0 low 0.0053 | O2: k0 high 0.0067 | S2: Strategy 1 | T2: Strategy 2 | U2: Optimal Control
C3: k0 = 0.0067 | F3: vaccination_rate | I3: bottom | K3: k1 = -0.1006 | L3: k1 = -0.1676 | M3: avg | N3: k1 high -0.1006 | O3: k1 low -0.1676 | S3: Constant Vaccination | T3: Actual alpha | U3: control_1 | V3: control_2 | W3: control_3 | X3: control_4 | Y3: control_5 | AB3: avg over rounds
C4: k1 = -0.1006 | F4: 0.02779241 | I4: k0 = 0.0053 | J4: 1 | K4: =F4 -> 0.02779241 | L4: 0.02779236 | M4: =AB4 -> 0.02447724 | N4: 0.02779235 | O4: 0.02779241 | S4: =$F$3 -> vaccination_rate | T4: =Reg_30days!AJ32 -> 0 | U4: 0.0245031 | V4: 0.0244278 | W4: 0.0244835 | X4: 0.0244886 | Y4: 0.0244832 | AB4: =AVERAGE(U4:Y4) -> 0.02447724
F5: 0.02779357 | I5: k1 = -0.1676 | J5: 2 | K5: =F5 -> 0.02779357 | L5: 0.02779371 | M5: =AB5 -> 0.02438572 | N5: 0.02779351 | O5: 0.02779376 | S5: =$F$3 -> vaccination_rate | T5: =Reg_30days!AJ33 -> 0 | U5: 0.0244224 | V5: 0.0243765 | W5: 0.0243693 | X5: 0.0243777 | Y5: 0.0243827 | AB5: =AVERAGE(U5:Y5) -> 0.02438572
F6: 0.02777892 | J6: 3 | K6: =F6 -> 0.02777892 | L6: 0.02777925 | M6: =AB6 -> 0.0242678 | N6: 0.02777886 | O6: 0.0277793 | S6: =$F$3 -> vaccination_rate | T6: =Reg_30days!AJ34 -> 0 | U6: 0.0243032 | V6: 0.0242313 | W6: 0.0242684 | X6: 0.0242707 | Y6: 0.0242654 | AB6: =AVERAGE(U6:Y6) -> 0.0242678
F7: 0.02776494 | J7: 4 | K7: =F7 -> 0.02776494 | L7: 0.02776547 | M7: =AB7 -> 0.02410956 | N7: 0.02776487 | O7: 0.02776553 | S7: =$F$3 -> vaccination_rate | T7: =Reg_30days!AJ35 -> 0 | U7: 0.0241285 | V7: 0.0241053 | W7: 0.0240692 | X7: 0.024107 | Y7: 0.0241378 | AB7: =AVERAGE(U7:Y7) -> 0.02410956
F8: 0.02774444 | J8: 5 | K8: =F8 -> 0.02774444 | L8: 0.02774524 | M8: =AB8 -> 0.02387136 | N8: 0.02774436 | O8: 0.0277453 | S8: =$F$3 -> vaccination_rate | T8: =Reg_30days!AJ36 -> 0 | U8: 0.02399 | V8: 0.0237615 | W8: 0.0239481 | X8: 0.0239716 | Y8: 0.0236856 | AB8: =AVERAGE(U8:Y8) -> 0.02387136
F9: 0.02771779 | J9: 6 | K9: =F9 -> 0.02771779 | L9: 0.02771905 | M9: =AB9 -> 0.02355274 | N9: 0.02771771 | O9: 0.02771912 | S9: =$F$3 -> vaccination_rate | T9: =Reg_30days!AJ37 -> 0 | U9: 0.0239124 | V9: 0.023483 | W9: 0.0234279 | X9: 0.0233801 | Y9: 0.0235603 | AB9: =AVERAGE(U9:Y9) -> 0.02355274
F10: 0.02769106 | J10: 7 | K10: =F10 -> 0.02769106 | L10: 0.02769274 | M10: =AB10 -> 0.02338316 | N10: 0.02769097 | O10: 0.0276928 | S10: =$F$3 -> vaccination_rate | T10: =Reg_30days!AJ38 -> 0 | U10: 0.0235616 | V10: 0.0234558 | W10: 0.0234109 | X10: 0.0231867 | Y10: 0.0233008 | AB10: =AVERAGE(U10:Y10) -> 0.02338316
F11: 0.02765664 | J11: 8 | K11: =F11 -> 0.02765664 | L11: 0.02765901 | M11: =AB11 -> 0.02316708 | N11: 0.02765656 | O11: 0.02765907 | S11: =$F$3 -> vaccination_rate | T11: =Reg_30days!AJ39 -> 0 | U11: 0.0231953 | V11: 0.0231481 | W11: 0.02331 | X11: 0.0231032 | Y11: 0.0230788 | AB11: =AVERAGE(U11:Y11) -> 0.02316708
F12: 0.02761797 | J12: 9 | K12: =F12 -> 0.02761797 | L12: 0.02762101 | M12: =AB12 -> 0.02305654 | N12: 0.02761784 | O12: 0.0276211 | S12: =$F$3 -> vaccination_rate | T12: =Reg_30days!AJ40 -> 0 | U12: 0.0230804 | V12: 0.0229861 | W12: 0.0233851 | X12: 0.0229123 | Y12: 0.0229188 | AB12: =AVERAGE(U12:Y12) -> 0.02305654
F13: 0.02759025 | J13: 10 | K13: =F13 -> 0.02759025 | L13: 0.02759398 | M13: =AB13 -> 0.02285692 | N13: 0.02759015 | O13: 0.02759403 | S13: =$F$3 -> vaccination_rate | T13: =Reg_30days!AJ41 -> 0 | U13: 0.022797 | V13: 0.0226103 | W13: 0.0232388 | X13: 0.0229475 | Y13: 0.022691 | AB13: =AVERAGE(U13:Y13) -> 0.02285692
F14: 0.02758413 | J14: 11 | K14: =F14 -> 0.02758413 | L14: 0.02758989 | M14: =AB14 -> 0.02267136 | N14: 0.02758616 | O14: 0.02758931 | S14: =$F$3 -> vaccination_rate | T14: =Reg_30days!AJ42 -> 0 | U14: 0.0225398 | V14: 0.0225778 | W14: 0.0229953 | X14: 0.0226186 | Y14: 0.0226253 | AB14: =AVERAGE(U14:Y14) -> 0.02267136
F15: 0.02747588 | J15: 12 | K15: =F15 -> 0.02747588 | L15: 0.02748173 | M15: =AB15 -> 0.02247434 | N15: 0.02747582 | O15: 0.02748176 | S15: =$F$3 -> vaccination_rate | T15: =Reg_30days!AJ43 -> 0 | U15: 0.0223361 | V15: 0.0225738 | W15: 0.022726 | X15: 0.0224946 | Y15: 0.0222412 | AB15: =AVERAGE(U15:Y15) -> 0.02247434
F16: 0.02734684 | J16: 13 | K16: =F16 -> 0.02734684 | L16: 0.02735633 | M16: =AB16 -> 0.02239424 | N16: 0.02734733 | O16: 0.027356 | S16: =$F$3 -> vaccination_rate | T16: =Reg_30days!AJ44 -> 0 | U16: 0.0221573 | V16: 0.0222858 | W16: 0.0225789 | X16: 0.0226736 | Y16: 0.0222756 | AB16: =AVERAGE(U16:Y16) -> 0.02239424
F17: 0.02724283 | J17: 14 | K17: =F17 -> 0.02724283 | L17: 0.0272533 | M17: =AB17 -> 0.02230826 | N17: 0.02724293 | O17: 0.02725343 | S17: =$F$3 -> vaccination_rate | T17: =Reg_30days!AJ45 -> 0 | U17: 0.0226141 | V17: 0.0222929 | W17: 0.0225579 | X17: 0.0223482 | Y17: 0.0217282 | AB17: =AVERAGE(U17:Y17) -> 0.02230826
... F63: 0.00424856 | J63: 60 | K63: =F63 -> 0.00424856 | L63: 0.00424851 | M63: =AB63 -> 0.005159404 | N63: 0.00424854 | O63: 0.00424854 | S63: =$F$3 -> vaccination_rate | T63: =Reg_30days!AJ91 -> 0 | U63: 0.00516643 | V63: 0.00515081 | W63: 0.00516471 | X63: 0.00515668 | Y63: 0.00515839 | AB63: =AVERAGE(U63:Y63) -> 0.005159404
S70: upper
E71: lower | AE71: base | AQ71: k1low | BC71: k0 low
AQ72: k0 high | BC72: k1 high
G84: Strategy | H84: Total Cost | I84: Healthcare | J84: Policy | K84: Economic | L84: Cost reduction
G85: No Vaccination | H85: 38.72 | I85: 9.5 | J85: 1.66 | K85: 27.56 | L85: =1-H88/H85 -> 0.17742769
G86: Constant Vaccination | H86: 34.28 | I86: 8.13 | J86: 3.08 | K86: 23.07 | L86: =1-H88/H86 -> 0.070886814
G87: Actual (Government) | H87: 31.4 | I87: 4.93 | J87: 3.35 | K87: 23.12
G88: Optimal | H88: 31.85 | I88: 4.42 | J88: 5.89 | K88: 21.54
E101: standard
E111: peak infected | F111: hosp | G111: icu
D112: no | AQ112: Strategy | AR112: Peak Infected | AS112: Peak Mild | AT112: Peak Hosp | AU112: Peak ICU | AV112: Peak Infected | AW112: Peak Mild | AX112: Peak Hosp | AY112: Peak ICU | BC112: Strategy | BD112: Peak Infected | BE112: Peak Mild | BF112: Peak Hosp | BG112: Peak ICU | BH112: Peak Infected | BI112: Peak Mild | BJ112: Peak Hosp | BK112: Peak ICU
D113: constant | AQ113: No Vaccination | AR113: 0.5662 | AS113: 0.5421 | AT113: 0.02185 | AU113: 0.01598 | AV113: =1-AR116/AR113 -> 0.0060049452 | AW113: =1-AS116/AS113 -> -0.027116768 | AX113: =1-AT116/AT113 -> 0.65629291 | AY113: =1-AU116/AU113 -> 0.8097622 | BC113: No Vaccination | BD113: 0.5662 | BE113: 0.5421 | BF113: 0.02185 | BG113: 0.01598 | BH113: =1-BD116/BD113 -> 0.0060049452 | BI113: =1-BE116/BE113 -> -0.026194429 | BJ113: =1-BF116/BF113 -> 0.65629291 | BK113: =1-BG116/BG113 -> 0.79411765
D114: optimal | S114: Strategy | T114: Peak Infected | U114: Peak Mild | V114: Peak Hosp | W114: Peak ICU | X114: Peak Infected | Y114: Peak Mild | Z114: Peak Hosp | AA114: Peak ICU | AQ114: Constant Vaccination | AR114: 0.5632 | AS114: 0.5395 | AT114: 0.02161 | AU114: 0.01551 | AV114: =1-AR116/AR114 -> 0.00071022727 | AW114: =1-AS116/AS114 -> -0.032066728 | AX114: =1-AT116/AT114 -> 0.65247571 | AY114: =1-AU116/AU114 -> 0.80399742 | BC114: Constant Vaccination | BD114: 0.5632 | BE114: 0.5395 | BF114: 0.02161 | BG114: 0.01551 | BH114: =1-BD116/BD114 -> 0.00071022727 | BI114: =1-BE116/BE114 -> -0.031139944 | BJ114: =1-BF116/BF114 -> 0.65247571 | BK114: =1-BG116/BG114 -> 0.78787879
F115: Strategy | G115: Peak Infected | H115: Peak Mild | I115: Peak Hosp | J115: Peak ICU | K115: Peak Infected | L115: Peak Mild | M115: Peak Hosp | N115: Peak ICU | S115: No Vaccination | T115: 0.5662 | U115: 0.5421 | V115: 0.02185 | W115: 0.01598 | X115: =1-T118/T115 -> 0.0061815613 | Y115: =1-U118/U115 -> -0.023058476 | Z115: =1-V118/V115 -> 0.65583524 | AA115: =1-W118/W115 -> 0.73404255 | AE115: Strategy | AF115: Peak Infected | AG115: Peak Mild | AH115: Peak Hosp | AI115: Peak ICU | AJ115: Peak Infected | AK115: Peak Mild | AL115: Peak Hosp | AM115: Peak ICU | AQ115: Actual (Government) | AR115: 0.5649 | AS115: 0.5564 | AT115: 0.00752 | AU115: 0.0043 | BC115: Actual (Government) | BD115: 0.5649 | BE115: 0.5569 | BF115: 0.00752 | BG115: 0.00408
